Workbook

Sheet Report
A1: ='Data Input'!$C$8 -> 46311 | B1: ='Data Input'!$N$8 -> 46313 | C1: ='Data Input'!$M$5 -> 46311.75 | D1: =('Data Input'!$C$9-'Data Input'!$C$8)*24 -> 0 | E1: ='Data Input'!$G$9*IF('Data Input'!$K$9="days",24,1)/48 -> 1 | K1: 0 | L1: 1 | M1: 2 | N1: 3 | O1: 4 | P1: 5 | Q1: 6 | R1: 7 | S1: 8 | T1: 9 | U1: 10 | V1: 11 | W1: 12 | X1: 13 | Y1: 14 | Z1: 15 | AA1: 16 | AB1: 17 | AC1: 18 | AD1: 19 | AE1: 20 | AF1: 21 | AG1: 22 | AH1: 23 | AI1: 24 | AJ1: 25 | AK1: 26 | AL1: 27 | AM1: 28 | AN1: 29 | AO1: 30 | AP1: 31 | AQ1: 32 | AR1: 33 | AS1: 34 | AT1: 35 | AU1: 36 | AV1: 37 | AW1: 38 | AX1: 39 | AY1: 40 | AZ1: 41 | BA1: 42 | BB1: 43 | BC1: 44 | BD1: 45 | BE1: 46 | BF1: 47
A3: EWR CULVERTS REPLACEMENT PHASE 2
A4: POSSESSION PROGRESS REPORT - PLANNED vs ACTUAL
A5: Culvert Replacement – Shutdown 03
A7: REPORT GENERATED | D7: =TEXT($C$1,"dddd dd-mmm-yyyy hh:mm")&" prepared by SAR IPMC – Planning" -> Friday 16-Oct-2026 18:00 prepared by SAR IPMC – Planning
A8: POSSESSION WINDOW | D8: =TEXT($A$1,"dddd dd-mmm-yyyy hh:mm")&" to "&TEXT($B$1,"dddd dd-mmm-yyyy hh:mm")&" = "&TEXT(($B$1-$A$1)*24,"0.0")&" hours" -> Friday 16-Oct-2026 00:00 to Sunday 18-Oct-2026 00:00 = 48.0 hours
A9: ELAPSED / REMAINING | D9: =TEXT(MEDIAN(0,($C$1-$A$1)*24,($B$1-$A$1)*24),"0.0")&" h elapsed "&TEXT(($B$1-$A$1)*24-MEDIAN(0,($C$1-$A$1)*24,($B$1-$A$1)*24),"0.0")&" h remaining" -> 18.0 h elapsed 30.0 h remaining
A11: SUMMARY - ALL LOCATIONS
A12: Location | C12: Status | D12: Planned Finish | E12: Forecast Finish | F12: Time Variance | G12: Plan % | H12: Actual % | I12: Buffer to Hand-back | K12: PROGRESS 0 - 100% coloured bar = actual % black line = DATA DATE
A13: C263 – KM 209+025 (1 cell) | C13: =IF(COUNTIF('Data Input'!X27:X52,"!*")>0,"CHECK INPUT",IF(I13<0,"AT RISK",IF(F13>0.1,"BEHIND",IF(I13<2,"TIGHT",IF(F13<-0.1,"AHEAD","ON TIME"))))) -> AT RISK | D13: =MAX('Data Input'!D27:D52) -> 46313.042 | E13: ='Data Input'!W53 -> 46313.792 | F13: =ROUND('Data Input'!X53,1) -> 18 | G13: =IF(SUM('Data Input'!E27:E52)=0,0,SUMPRODUCT('Data Input'!E27:E52,'Data Input'!T27:T52)/SUM('Data Input'!E27:E52)) -> 0.39215686 | H13: =IF(SUM('Data Input'!E27:E52)=0,0,SUMPRODUCT('Data Input'!E27:E52,'Data Input'!S27:S52)/SUM('Data Input'!E27:E52)) -> 0 | I13: =ROUND(('Data Input'!$N$8-E13)*24,1) -> -19
A14: C265 – KM 210+525 (3 cells) | C14: =IF(COUNTIF('Data Input'!X57:X82,"!*")>0,"CHECK INPUT",IF(I14<0,"AT RISK",IF(F14>0.1,"BEHIND",IF(I14<2,"TIGHT",IF(F14<-0.1,"AHEAD","ON TIME"))))) -> AT RISK | D14: =MAX('Data Input'!D57:D82) -> 46312.917 | E14: ='Data Input'!W83 -> 46313.667 | F14: =ROUND('Data Input'!X83,1) -> 18 | G14: =IF(SUM('Data Input'!E57:E82)=0,0,SUMPRODUCT('Data Input'!E57:E82,'Data Input'!T57:T82)/SUM('Data Input'!E57:E82)) -> 0.41666667 | H14: =IF(SUM('Data Input'!E57:E82)=0,0,SUMPRODUCT('Data Input'!E57:E82,'Data Input'!S57:S82)/SUM('Data Input'!E57:E82)) -> 0 | I14: =ROUND(('Data Input'!$N$8-E14)*24,1) -> -16
A15: C267 – KM 212+400 (3 cells) | C15: =IF(COUNTIF('Data Input'!X87:X112,"!*")>0,"CHECK INPUT",IF(I15<0,"AT RISK",IF(F15>0.1,"BEHIND",IF(I15<2,"TIGHT",IF(F15<-0.1,"AHEAD","ON TIME"))))) -> AT RISK | D15: =MAX('Data Input'!D87:D112) -> 46312.625 | E15: ='Data Input'!W113 -> 46313.375 | F15: =ROUND('Data Input'!X113,1) -> 18 | G15: =IF(SUM('Data Input'!E87:E112)=0,0,SUMPRODUCT('Data Input'!E87:E112,'Data Input'!T87:T112)/SUM('Data Input'!E87:E112)) -> 0.48780488 | H15: =IF(SUM('Data Input'!E87:E112)=0,0,SUMPRODUCT('Data Input'!E87:E112,'Data Input'!S87:S112)/SUM('Data Input'!E87:E112)) -> 0 | I15: =ROUND(('Data Input'!$N$8-E15)*24,1) -> -9
A16: C288 – KM 337+391 (3 cells) | C16: =IF(COUNTIF('Data Input'!X117:X142,"!*")>0,"CHECK INPUT",IF(I16<0,"AT RISK",IF(F16>0.1,"BEHIND",IF(I16<2,"TIGHT",IF(F16<-0.1,"AHEAD","ON TIME"))))) -> AT RISK | D16: =MAX('Data Input'!D117:D142) -> 46312.958 | E16: ='Data Input'!W143 -> 46313.708 | F16: =ROUND('Data Input'!X143,1) -> 18 | G16: =IF(SUM('Data Input'!E117:E142)=0,0,SUMPRODUCT('Data Input'!E117:E142,'Data Input'!T117:T142)/SUM('Data Input'!E117:E142)) -> 0.38297872 | H16: =IF(SUM('Data Input'!E117:E142)=0,0,SUMPRODUCT('Data Input'!E117:E142,'Data Input'!S117:S142)/SUM('Data Input'!E117:E142)) -> 0 | I16: =ROUND(('Data Input'!$N$8-E16)*24,1) -> -17
A17: C289 – KM 338+491 (3 cells) | C17: =IF(COUNTIF('Data Input'!X147:X172,"!*")>0,"CHECK INPUT",IF(I17<0,"AT RISK",IF(F17>0.1,"BEHIND",IF(I17<2,"TIGHT",IF(F17<-0.1,"AHEAD","ON TIME"))))) -> AT RISK | D17: =MAX('Data Input'!D147:D172) -> 46313.042 | E17: ='Data Input'!W173 -> 46313.792 | F17: =ROUND('Data Input'!X173,1) -> 18 | G17: =IF(SUM('Data Input'!E147:E172)=0,0,SUMPRODUCT('Data Input'!E147:E172,'Data Input'!T147:T172)/SUM('Data Input'!E147:E172)) -> 0.39215686 | H17: =IF(SUM('Data Input'!E147:E172)=0,0,SUMPRODUCT('Data Input'!E147:E172,'Data Input'!S147:S172)/SUM('Data Input'!E147:E172)) -> 0 | I17: =ROUND(('Data Input'!$N$8-E17)*24,1) -> -19
A18: ALL LOCATIONS | C18: =IF(MIN(I13:I17)<0,"AT RISK",IF(MAX(F13:F17)>0.1,"BEHIND",IF(MIN(I13:I17)<2,"TIGHT","ON TIME"))) -> AT RISK | D18: =MAX(D13:D17) -> 46313.042 | E18: =MAX(E13:E17) -> 46313.792 | F18: =ROUND(MAX(F13:F17),1) -> 18 | G18: =AVERAGE(G13:G17) -> 0.4143528 | H18: =AVERAGE(H13:H17) -> 0 | I18: =ROUND(MIN(I13:I17),1) -> -19
A20: SITE LAYOUT - SCHEMATIC OVERVIEW
A37: EWR CULVERTS REPLACEMENT PHASE 2 - CULVERT C263 - KM 209+025 - 1 CELL - TSO OTMP / Station 29
A38: =" 1 cell ACTUAL "&TEXT(H13,"0%")&" PLANNED "&TEXT(G13,"0%")&" PLAN FINISH "&TEXT(D13,"ddd dd-mmm hh:mm") -> 1 cell ACTUAL 0% PLANNED 39% PLAN FINISH Sun 18-Oct 01:00 | K38: =C13&" FORECAST "&TEXT(E13,"ddd dd-mmm hh:mm")&" "&TEXT(ABS(F13),"0.0")&IF(F13>0," h LATE",IF(F13<0," h EARLY"," h")) -> AT RISK FORECAST Sun 18-Oct 19:00 18.0 h LATE
A39: No | B39: Activity | C39: Status | D39: Planned Finish | E39: Forecast Finish | F39: Time Variance | G39: Plan % | H39: Act. % | I39: Buffer to Hand-back | K39: =UPPER(TEXT($A$1+($D$1+0*$E$1)/24,"ddd dd-mmm hh:mm")&" to "&TEXT($A$1+($D$1+24*$E$1)/24,"ddd dd-mmm hh:mm")) -> FRI 16-OCT 00:00 TO SAT 17-OCT 00:00 | AI39: =UPPER(TEXT($A$1+($D$1+24*$E$1)/24,"ddd dd-mmm hh:mm")&" to "&TEXT($A$1+($D$1+48*$E$1)/24,"ddd dd-mmm hh:mm")) -> SAT 17-OCT 00:00 TO SUN 18-OCT 00:00
K40: =TEXT($A$1+($D$1+0*$E$1)/24,"hh:mm")&" - "&TEXT($A$1+($D$1+6*$E$1)/24,"hh:mm") -> 00:00 - 06:00 | Q40: =TEXT($A$1+($D$1+6*$E$1)/24,"hh:mm")&" - "&TEXT($A$1+($D$1+12*$E$1)/24,"hh:mm") -> 06:00 - 12:00 | W40: =TEXT($A$1+($D$1+12*$E$1)/24,"hh:mm")&" - "&TEXT($A$1+($D$1+18*$E$1)/24,"hh:mm") -> 12:00 - 18:00 | AC40: =TEXT($A$1+($D$1+18*$E$1)/24,"hh:mm")&" - "&TEXT($A$1+($D$1+24*$E$1)/24,"hh:mm") -> 18:00 - 00:00 | AI40: =TEXT($A$1+($D$1+24*$E$1)/24,"hh:mm")&" - "&TEXT($A$1+($D$1+30*$E$1)/24,"hh:mm") -> 00:00 - 06:00 | AO40: =TEXT($A$1+($D$1+30*$E$1)/24,"hh:mm")&" - "&TEXT($A$1+($D$1+36*$E$1)/24,"hh:mm") -> 06:00 - 12:00 | AU40: =TEXT($A$1+($D$1+36*$E$1)/24,"hh:mm")&" - "&TEXT($A$1+($D$1+42*$E$1)/24,"hh:mm") -> 12:00 - 18:00 | BA40: =TEXT($A$1+($D$1+42*$E$1)/24,"hh:mm")&" - "&TEXT($A$1+($D$1+48*$E$1)/24,"hh:mm") -> 18:00 - 00:00
A41: ='Data Input'!A27 -> 1 | B41: ='Data Input'!B27 -> OTMP moves from station 29 to Main Line 1 | C41: ='Data Input'!O27 -> NOT STARTED - LATE | D41: ='Data Input'!D27 -> 46311.042 | E41: ='Data Input'!D27+'Data Input'!Y27/24 -> 46311.792 | F41: ='Data Input'!Y27 -> 18 | G41: ='Data Input'!T27 -> 1 | H41: ='Data Input'!S27 -> 0 | J41: P | BH41: =('Data Input'!C27-$A$1)*24 -> 0 | BI41: =('Data Input'!D27-$A$1)*24 -> 1 | BJ41: 1 | BO41: -999 | BP41: -999
J42: A | BH42: =IF($BK42="",-999,($BK42-$A$1)*24) -> -999 | BI42: =IF($BK42="",-999,(IF($BL42<>"",$BL42,IF($C$1>$BK42,$C$1,$BK42+MAX('Data Input'!E27*$BM42,0.5)/24))-$A$1)*24) -> -999 | BJ42: =IF($BK42="",0,IF($BM42>=1,IF($BN42<=0,2,3),IF($BN42<=0,4,5))) -> 0 | BK42: =IF('Data Input'!Q27="","",'Data Input'!Q27) | BL42: =IF('Data Input'!R27="","",'Data Input'!R27) | BM42: ='Data Input'!S27 -> 0 | BN42: ='Data Input'!Y27 -> 18 | BO42: =IF($BM42>=1,-999,MAX(($C$1-$A$1)*24,IF($BK42<>"",$BI42,$BP42-'Data Input'!E27))) -> 18 | BP42: =('Data Input'!D27+'Data Input'!Y27/24-$A$1)*24 -> 19
A43: ='Data Input'!A28 -> 2 | B43: ='Data Input'!B28 -> Track removal & panel evacuation (Line 1) | C43: ='Data Input'!O28 -> NOT STARTED - LATE | D43: ='Data Input'!D28 -> 46311.083 | E43: ='Data Input'!D28+'Data Input'!Y28/24 -> 46311.833 | F43: ='Data Input'!Y28 -> 18 | G43: ='Data Input'!T28 -> 1 | H43: ='Data Input'!S28 -> 0 | J43: P | BH43: =('Data Input'!C28-$A$1)*24 -> 1 | BI43: =('Data Input'!D28-$A$1)*24 -> 2 | BJ43: 1 | BO43: -999 | BP43: -999
J44: A | BH44: =IF($BK44="",-999,($BK44-$A$1)*24) -> -999 | BI44: =IF($BK44="",-999,(IF($BL44<>"",$BL44,IF($C$1>$BK44,$C$1,$BK44+MAX('Data Input'!E28*$BM44,0.5)/24))-$A$1)*24) -> -999 | BJ44: =IF($BK44="",0,IF($BM44>=1,IF($BN44<=0,2,3),IF($BN44<=0,4,5))) -> 0 | BK44: =IF('Data Input'!Q28="","",'Data Input'!Q28) | BL44: =IF('Data Input'!R28="","",'Data Input'!R28) | BM44: ='Data Input'!S28 -> 0 | BN44: ='Data Input'!Y28 -> 18 | BO44: =IF($BM44>=1,-999,MAX(($C$1-$A$1)*24,IF($BK44<>"",$BI44,$BP44-'Data Input'!E28))) -> 19 | BP44: =('Data Input'!D28+'Data Input'!Y28/24-$A$1)*24 -> 20
A45: ='Data Input'!A29 -> 3 | B45: ='Data Input'!B29 -> Track removal & panel evacuation (Line 3) | C45: ='Data Input'!O29 -> NOT STARTED - LATE | D45: ='Data Input'!D29 -> 46311.042 | E45: ='Data Input'!D29+'Data Input'!Y29/24 -> 46311.792 | F45: ='Data Input'!Y29 -> 18 | G45: ='Data Input'!T29 -> 1 | H45: ='Data Input'!S29 -> 0 | J45: P | BH45: =('Data Input'!C29-$A$1)*24 -> 0 | BI45: =('Data Input'!D29-$A$1)*24 -> 1 | BJ45: 1 | BO45: -999 | BP45: -999
J46: A | BH46: =IF($BK46="",-999,($BK46-$A$1)*24) -> -999 | BI46: =IF($BK46="",-999,(IF($BL46<>"",$BL46,IF($C$1>$BK46,$C$1,$BK46+MAX('Data Input'!E29*$BM46,0.5)/24))-$A$1)*24) -> -999 | BJ46: =IF($BK46="",0,IF($BM46>=1,IF($BN46<=0,2,3),IF($BN46<=0,4,5))) -> 0 | BK46: =IF('Data Input'!Q29="","",'Data Input'!Q29) | BL46: =IF('Data Input'!R29="","",'Data Input'!R29) | BM46: ='Data Input'!S29 -> 0 | BN46: ='Data Input'!Y29 -> 18 | BO46: =IF($BM46>=1,-999,MAX(($C$1-$A$1)*24,IF($BK46<>"",$BI46,$BP46-'Data Input'!E29))) -> 18 | BP46: =('Data Input'!D29+'Data Input'!Y29/24-$A$1)*24 -> 19
A47: ='Data Input'!A30 -> 4 | B47: ='Data Input'!B30 -> Ballast removal | C47: ='Data Input'!O30 -> NOT STARTED - LATE | D47: ='Data Input'!D30 -> 46311.083 | E47: ='Data Input'!D30+'Data Input'!Y30/24 -> 46311.833 | F47: ='Data Input'!Y30 -> 18 | G47: ='Data Input'!T30 -> 1 | H47: ='Data Input'!S30 -> 0 | J47: P | BH47: =('Data Input'!C30-$A$1)*24 -> 1 | BI47: =('Data Input'!D30-$A$1)*24 -> 2 | BJ47: 1 | BO47: -999 | BP47: -999
J48: A | BH48: =IF($BK48="",-999,($BK48-$A$1)*24) -> -999 | BI48: =IF($BK48="",-999,(IF($BL48<>"",$BL48,IF($C$1>$BK48,$C$1,$BK48+MAX('Data Input'!E30*$BM48,0.5)/24))-$A$1)*24) -> -999 | BJ48: =IF($BK48="",0,IF($BM48>=1,IF($BN48<=0,2,3),IF($BN48<=0,4,5))) -> 0 | BK48: =IF('Data Input'!Q30="","",'Data Input'!Q30) | BL48: =IF('Data Input'!R30="","",'Data Input'!R30) | BM48: ='Data Input'!S30 -> 0 | BN48: ='Data Input'!Y30 -> 18 | BO48: =IF($BM48>=1,-999,MAX(($C$1-$A$1)*24,IF($BK48<>"",$BI48,$BP48-'Data Input'!E30))) -> 19 | BP48: =('Data Input'!D30+'Data Input'!Y30/24-$A$1)*24 -> 20
A49: ='Data Input'!A31 -> 5 | B49: ='Data Input'!B31 -> Cutting & removal around existing culvert | C49: ='Data Input'!O31 -> NOT STARTED - LATE | D49: ='Data Input'!D31 -> 46311.208 | E49: ='Data Input'!D31+'Data Input'!Y31/24 -> 46311.958 | F49: ='Data Input'!Y31 -> 18 | G49: ='Data Input'!T31 -> 1 | H49: ='Data Input'!S31 -> 0 | J49: P | BH49: =('Data Input'!C31-$A$1)*24 -> 2 | BI49: =('Data Input'!D31-$A$1)*24 -> 5 | BJ49: 1 | BO49: -999 | BP49: -999
J50: A | BH50: =IF($BK50="",-999,($BK50-$A$1)*24) -> -999 | BI50: =IF($BK50="",-999,(IF($BL50<>"",$BL50,IF($C$1>$BK50,$C$1,$BK50+MAX('Data Input'!E31*$BM50,0.5)/24))-$A$1)*24) -> -999 | BJ50: =IF($BK50="",0,IF($BM50>=1,IF($BN50<=0,2,3),IF($BN50<=0,4,5))) -> 0 | BK50: =IF('Data Input'!Q31="","",'Data Input'!Q31) | BL50: =IF('Data Input'!R31="","",'Data Input'!R31) | BM50: ='Data Input'!S31 -> 0 | BN50: ='Data Input'!Y31 -> 18 | BO50: =IF($BM50>=1,-999,MAX(($C$1-$A$1)*24,IF($BK50<>"",$BI50,$BP50-'Data Input'!E31))) -> 20 | BP50: =('Data Input'!D31+'Data Input'!Y31/24-$A$1)*24 -> 23
A51: ='Data Input'!A32 -> 6 | B51: ='Data Input'!B32 -> Demolition of existing culvert | C51: ='Data Input'!O32 -> NOT STARTED - LATE | D51: ='Data Input'!D32 -> 46311.375 | E51: ='Data Input'!D32+'Data Input'!Y32/24 -> 46312.125 | F51: ='Data Input'!Y32 -> 18 | G51: ='Data Input'!T32 -> 1 | H51: ='Data Input'!S32 -> 0 | J51: P | BH51: =('Data Input'!C32-$A$1)*24 -> 5 | BI51: =('Data Input'!D32-$A$1)*24 -> 9 | BJ51: 1 | BO51: -999 | BP51: -999
J52: A | BH52: =IF($BK52="",-999,($BK52-$A$1)*24) -> -999 | BI52: =IF($BK52="",-999,(IF($BL52<>"",$BL52,IF($C$1>$BK52,$C$1,$BK52+MAX('Data Input'!E32*$BM52,0.5)/24))-$A$1)*24) -> -999 | BJ52: =IF($BK52="",0,IF($BM52>=1,IF($BN52<=0,2,3),IF($BN52<=0,4,5))) -> 0 | BK52: =IF('Data Input'!Q32="","",'Data Input'!Q32) | BL52: =IF('Data Input'!R32="","",'Data Input'!R32) | BM52: ='Data Input'!S32 -> 0 | BN52: ='Data Input'!Y32 -> 18 | BO52: =IF($BM52>=1,-999,MAX(($C$1-$A$1)*24,IF($BK52<>"",$BI52,$BP52-'Data Input'!E32))) -> 23 | BP52: =('Data Input'!D32+'Data Input'!Y32/24-$A$1)*24 -> 27
A53: ='Data Input'!A33 -> 7 | B53: ='Data Input'!B33 -> Surface preparation for precast installation | C53: ='Data Input'!O33 -> NOT STARTED - LATE | D53: ='Data Input'!D33 -> 46311.458 | E53: ='Data Input'!D33+'Data Input'!Y33/24 -> 46312.208 | F53: ='Data Input'!Y33 -> 18 | G53: ='Data Input'!T33 -> 1 | H53: ='Data Input'!S33 -> 0 | J53: P | BH53: =('Data Input'!C33-$A$1)*24 -> 9 | BI53: =('Data Input'!D33-$A$1)*24 -> 11 | BJ53: 1 | BO53: -999 | BP53: -999
J54: A | BH54: =IF($BK54="",-999,($BK54-$A$1)*24) -> -999 | BI54: =IF($BK54="",-999,(IF($BL54<>"",$BL54,IF($C$1>$BK54,$C$1,$BK54+MAX('Data Input'!E33*$BM54,0.5)/24))-$A$1)*24) -> -999 | BJ54: =IF($BK54="",0,IF($BM54>=1,IF($BN54<=0,2,3),IF($BN54<=0,4,5))) -> 0 | BK54: =IF('Data Input'!Q33="","",'Data Input'!Q33) | BL54: =IF('Data Input'!R33="","",'Data Input'!R33) | BM54: ='Data Input'!S33 -> 0 | BN54: ='Data Input'!Y33 -> 18 | BO54: =IF($BM54>=1,-999,MAX(($C$1-$A$1)*24,IF($BK54<>"",$BI54,$BP54-'Data Input'!E33))) -> 27 | BP54: =('Data Input'!D33+'Data Input'!Y33/24-$A$1)*24 -> 29
A55: ='Data Input'!A34 -> 8 | B55: ='Data Input'!B34 -> Installation of new precast culvert | C55: ='Data Input'!O34 -> NOT STARTED - LATE | D55: ='Data Input'!D34 -> 46311.667 | E55: ='Data Input'!D34+'Data Input'!Y34/24 -> 46312.417 | F55: ='Data Input'!Y34 -> 18 | G55: ='Data Input'!T34 -> 1 | H55: ='Data Input'!S34 -> 0 | J55: P | BH55: =('Data Input'!C34-$A$1)*24 -> 11 | BI55: =('Data Input'!D34-$A$1)*24 -> 16 | BJ55: 1 | BO55: -999 | BP55: -999
J56: A | BH56: =IF($BK56="",-999,($BK56-$A$1)*24) -> -999 | BI56: =IF($BK56="",-999,(IF($BL56<>"",$BL56,IF($C$1>$BK56,$C$1,$BK56+MAX('Data Input'!E34*$BM56,0.5)/24))-$A$1)*24) -> -999 | BJ56: =IF($BK56="",0,IF($BM56>=1,IF($BN56<=0,2,3),IF($BN56<=0,4,5))) -> 0 | BK56: =IF('Data Input'!Q34="","",'Data Input'!Q34) | BL56: =IF('Data Input'!R34="","",'Data Input'!R34) | BM56: ='Data Input'!S34 -> 0 | BN56: ='Data Input'!Y34 -> 18 | BO56: =IF($BM56>=1,-999,MAX(($C$1-$A$1)*24,IF($BK56<>"",$BI56,$BP56-'Data Input'!E34))) -> 29 | BP56: =('Data Input'!D34+'Data Input'!Y34/24-$A$1)*24 -> 34
A57: ='Data Input'!A35 -> 9 | B57: ='Data Input'!B35 -> Apply sealant to the culvert | C57: ='Data Input'!O35 -> NOT STARTED - LATE | D57: ='Data Input'!D35 -> 46311.75 | E57: ='Data Input'!D35+'Data Input'!Y35/24 -> 46312.5 | F57: ='Data Input'!Y35 -> 18 | G57: ='Data Input'!T35 -> 1 | H57: ='Data Input'!S35 -> 0 | J57: P | BH57: =('Data Input'!C35-$A$1)*24 -> 16 | BI57: =('Data Input'!D35-$A$1)*24 -> 18 | BJ57: 1 | BO57: -999 | BP57: -999
J58: A | BH58: =IF($BK58="",-999,($BK58-$A$1)*24) -> -999 | BI58: =IF($BK58="",-999,(IF($BL58<>"",$BL58,IF($C$1>$BK58,$C$1,$BK58+MAX('Data Input'!E35*$BM58,0.5)/24))-$A$1)*24) -> -999 | BJ58: =IF($BK58="",0,IF($BM58>=1,IF($BN58<=0,2,3),IF($BN58<=0,4,5))) -> 0 | BK58: =IF('Data Input'!Q35="","",'Data Input'!Q35) | BL58: =IF('Data Input'!R35="","",'Data Input'!R35) | BM58: ='Data Input'!S35 -> 0 | BN58: ='Data Input'!Y35 -> 18 | BO58: =IF($BM58>=1,-999,MAX(($C$1-$A$1)*24,IF($BK58<>"",$BI58,$BP58-'Data Input'!E35))) -> 34 | BP58: =('Data Input'!D35+'Data Input'!Y35/24-$A$1)*24 -> 36
A59: ='Data Input'!A36 -> 10 | B59: ='Data Input'!B36 -> Backfill around culvert to subgrade level | C59: ='Data Input'!O36 -> NOT STARTED - LATE | D59: ='Data Input'!D36 -> 46311.958 | E59: ='Data Input'!D36+'Data Input'!Y36/24 -> 46312.708 | F59: ='Data Input'!Y36 -> 18 | G59: ='Data Input'!T36 -> 0 | H59: ='Data Input'!S36 -> 0 | J59: P | BH59: =('Data Input'!C36-$A$1)*24 -> 18 | BI59: =('Data Input'!D36-$A$1)*24 -> 23 | BJ59: 1 | BO59: -999 | BP59: -999
J60: A | BH60: =IF($BK60="",-999,($BK60-$A$1)*24) -> -999 | BI60: =IF($BK60="",-999,(IF($BL60<>"",$BL60,IF($C$1>$BK60,$C$1,$BK60+MAX('Data Input'!E36*$BM60,0.5)/24))-$A$1)*24) -> -999 | BJ60: =IF($BK60="",0,IF($BM60>=1,IF($BN60<=0,2,3),IF($BN60<=0,4,5))) -> 0 | BK60: =IF('Data Input'!Q36="","",'Data Input'!Q36) | BL60: =IF('Data Input'!R36="","",'Data Input'!R36) | BM60: ='Data Input'!S36 -> 0 | BN60: ='Data Input'!Y36 -> 18 | BO60: =IF($BM60>=1,-999,MAX(($C$1-$A$1)*24,IF($BK60<>"",$BI60,$BP60-'Data Input'!E36))) -> 36 | BP60: =('Data Input'!D36+'Data Input'!Y36/24-$A$1)*24 -> 41
...

Sheet Site Layouts
A2: EWR CULVERTS REPLACEMENT PHASE 2 – SHUTDOWN 03 – SITE LAYOUTS
A3: CULVERTS C263 · C265 · C267 – KM 209+025 / 210+525 / 212+400
A4: TSO OTMP stabled at Station 29 (KM 223) before the shutdown, then run out to Main Line 1 and Main Line 3. Hofuf lies to the west, Riyadh to the east.
A35: EWR CULVERTS REPLACEMENT PHASE 2 – SHUTDOWN 03 – SITE LAYOUTS
A36: CULVERTS C288 · C289 – KM 337+391 / 338+491
A37: SABATCO OTMP works Line 1 at both culverts (Phase 1), then transfers to Line 3 via Station 35 (Phase 2). Station 33 lies at KM 309.
A68: Diagrams as supplied with the Shutdown 03 pack. They show OTMP movement phases for each culvert group, not individual culvert cross-sections.

Sheet Data Input
A1: SAR - POSSESSION PROGRESS REPORT | DATA INPUT AND SETTINGS
A2: Everything below drives the report. Yellow cells are yours to edit - every other cell is locked and calculated. | Z2: FS
Z3: SS
A4: PROJECT NAME | C4: EWR CULVERTS REPLACEMENT PHASE 2 | I4: REPORT TITLE | K4: POSSESSION PROGRESS REPORT - PLANNED vs ACTUAL | Z4: FF
A5: SUBTITLE | C5: Culvert Replacement – Shutdown 03 | G5: PREPARED BY | I5: SAR IPMC – Planning | K5: REPORT CUT-OFF | M5: 46311.75 | Z5: SF
A7: POSSESSION WINDOW
A8: WINDOW STARTS | C8: 46311 | E8: DURATION | G8: 48 | I8: UNIT | K8: hours | L8: WINDOW ENDS | N8: =$C$8+$G$8*IF($K$8="days",1,1/24) -> 46313 | Z8: hours
A9: GANTT STARTS | C9: =$C$8 -> 46311 | E9: GANTT SPAN | G9: 48 | I9: UNIT | K9: hours | L9: ONE COLUMN = | N9: =TEXT($G$9*IF($K$9="days",24,1)/48*60,"0")&" min" -> 60 min | Z9: days
A10: TOTAL HOURS | C10: =($N$8-$C$8)*24 -> 48 | E10: ELAPSED | G10: =TEXT(MEDIAN(0,($M$5-$C$8)*24,$C$10),"0.0")&" h of "&TEXT($C$10,"0.0")&" h" -> 18.0 h of 48.0 h | K10: LOCATIONS | M10: 5 | N10: ACTIVITIES | O10: 26
A11: The Gantt is always 48 columns wide - a shorter span gives finer columns. Delivered with 5 locations x 26 activities per location; blank an ACTIVITY name to switch that row off.
Z12: =INT($C$8)+0 -> 46311
A13: LOCATIONS | Z13: =INT($C$8)+1 -> 46312
A14: No | B14: LOCATION NAME | I14: SCOPE / SUB-TITLE SHOWN ON THE PAGE | Z14: =INT($C$8)+2 -> 46313
A15: 1 | B15: C263 – KM 209+025 | I15: 1 cell │ Main Line 1 & Main Line 3 │ TSO OTMP from Station 29 | Z15: =INT($C$8)+3 -> 46314
A16: 2 | B16: C265 – KM 210+525 | I16: 3 cells │ Main Line 1 & Main Line 3 │ TSO OTMP from Station 29 | Z16: =INT($C$8)+4 -> 46315
A17: 3 | B17: C267 – KM 212+400 | I17: 3 cells │ Main Line 1 & Main Line 3 │ TSO OTMP from Station 29
A18: 4 | B18: C288 – KM 337+391 | I18: 3 cells │ Main Line 1 & Main Line 3 │ SABATCO OTMP from Station 35
A19: 5 | B19: C289 – KM 338+491 | I19: 3 cells │ Main Line 1 & Main Line 3 │ SABATCO OTMP from Station 35
A25: =IF($B$15="","LOCATION 1 - not used"," LOCATION 1 - "&$B$15) -> LOCATION 1 - C263 – KM 209+025
A26: No | B26: ACTIVITY (leave blank to switch the row off) | C26: Planned Start | D26: Planned Finish | E26: DUR (h) | F26: PRED No | G26: REL | H26: LAG (h) | I26: ACT START Date | J26: ACT START Time | K26: ACT FINISH Date | L26: ACT FINISH Time | M26: ACT Dur | N26: % COMP | O26: STATUS (auto) | P26: REMARKS
A27: =IF(OR($B27="",1>$O$10),"",1) -> 1 | B27: OTMP moves from station 29 to Main Line 1 | C27: =IF(OR($B27="",1>$O$10),"",IF($F27=0,$C$8,IF($G27="SS",OFFSET($C$26,$F27,0)+$H27/24,IF($G27="FF",OFFSET($D$26,$F27,0)+$H27/24-$E27/24,IF($G27="SF",OFFSET($C$26,$F27,0)+$H27/24-$E27/24,OFFSET($D$26,$F27,0)+$H27/24))))) -> 46311 | D27: =IF(OR($B27="",1>$O$10),"",$C27+$E27/24) -> 46311.042 | E27: 1 | F27: 0 | G27: FS | H27: 0 | M27: =IF(OR($Q27="",$R27="",$V27=1),"",($R27-$Q27)*24) | O27: =IF(OR($B27="",1>$O$10),"",IF($AB27=1,"! CHECK LINK",IF($V27=1,"! CHECK DATES",IF($S27=1,IF($R27="","Completed",IF($R27<$D27,"Completed - Ahead",IF($R27<=$D27+1/1440,"Completed - On Time","Completed - Delayed"))),IF($Q27<>"",IF($Y27<=0.1,"In Progress - On Track","In Progress - BEHIND"),IF($M$5<$C27,"Not Started","NOT STARTED - LATE")))))) -> NOT STARTED - LATE | Q27: =IF($I27="","",$I27+IF($J27="",0,$J27)) | R27: =IF($K27="","",$K27+IF($L27="",0,$L27)) | S27: =IF($V27=1,0,IF($R27<>"",1,IF($N27="",0,$N27))) -> 0 | T27: =IF(OR($B27="",$E27=0),0,MEDIAN(0,($M$5-$C27)/($E27/24),1)) -> 1 | U27: =($S27-$T27)*$E27 -> -1 | V27: =IF(OR(AND($Q27<>"",$Q27<$C$8),AND($Q27<>"",$R27<>"",$R27<$Q27),AND($R27<>"",$Q27="")),1,0) -> 0 | W27: =IF($B27="","",IF($S27=1,IF($R27<>"",$R27,$D27),IF($Q27<>"",MAX($M$5,$Q27)+$E27*(1-$S27)/24,MAX($M$5,$C27)+$E27/24))) -> 46311.792 | X27: =IF($B27="","",ROUND(($W27-$D27)*24,1)) -> 18 | Y27: =IF($B27="","",$X27) -> 18 | AB27: =IF(AND($B27<>"",$F27>=1),1,0) -> 0
A28: =IF(OR($B28="",2>$O$10),"",2) -> 2 | B28: Track removal & panel evacuation (Line 1) | C28: =IF(OR($B28="",2>$O$10),"",IF($F28=0,$C$8,IF($G28="SS",OFFSET($C$26,$F28,0)+$H28/24,IF($G28="FF",OFFSET($D$26,$F28,0)+$H28/24-$E28/24,IF($G28="SF",OFFSET($C$26,$F28,0)+$H28/24-$E28/24,OFFSET($D$26,$F28,0)+$H28/24))))) -> 46311.042 | D28: =IF(OR($B28="",2>$O$10),"",$C28+$E28/24) -> 46311.083 | E28: 1 | F28: 1 | G28: FS | H28: 0 | M28: =IF(OR($Q28="",$R28="",$V28=1),"",($R28-$Q28)*24) | O28: =IF(OR($B28="",2>$O$10),"",IF($AB28=1,"! CHECK LINK",IF($V28=1,"! CHECK DATES",IF($S28=1,IF($R28="","Completed",IF($R28<$D28,"Completed - Ahead",IF($R28<=$D28+1/1440,"Completed - On Time","Completed - Delayed"))),IF($Q28<>"",IF($Y28<=0.1,"In Progress - On Track","In Progress - BEHIND"),IF($M$5<$C28,"Not Started","NOT STARTED - LATE")))))) -> NOT STARTED - LATE | Q28: =IF($I28="","",$I28+IF($J28="",0,$J28)) | R28: =IF($K28="","",$K28+IF($L28="",0,$L28)) | S28: =IF($V28=1,0,IF($R28<>"",1,IF($N28="",0,$N28))) -> 0 | T28: =IF(OR($B28="",$E28=0),0,MEDIAN(0,($M$5-$C28)/($E28/24),1)) -> 1 | U28: =($S28-$T28)*$E28 -> -1 | V28: =IF(OR(AND($Q28<>"",$Q28<$C$8),AND($Q28<>"",$R28<>"",$R28<$Q28),AND($R28<>"",$Q28="")),1,0) -> 0 | W28: =IF($B28="","",IF($S28=1,IF($R28<>"",$R28,$D28),IF($Q28<>"",MAX($M$5,$Q28)+$E28*(1-$S28)/24,MAX($M$5,$C28)+$E28/24))) -> 46311.792 | X28: =IF($B28="","",ROUND(($W28-$D28)*24,1)) -> 17 | Y28: =IF($B28="","",IF($Q28<>"",$X28,IF($X28>0,MAX($X28,IF($Y27="",0,IF($Y27>0,$Y27-MAX(0,($C28-$D27)*24),$Y27))),IF($Y27="",0,IF($Y27>0,$Y27-MAX(0,($C28-$D27)*24),$Y27))))) -> 18 | AB28: =IF(AND($B28<>"",$F28>=2),1,0) -> 0
A29: =IF(OR($B29="",3>$O$10),"",3) -> 3 | B29: Track removal & panel evacuation (Line 3) | C29: =IF(OR($B29="",3>$O$10),"",IF($F29=0,$C$8,IF($G29="SS",OFFSET($C$26,$F29,0)+$H29/24,IF($G29="FF",OFFSET($D$26,$F29,0)+$H29/24-$E29/24,IF($G29="SF",OFFSET($C$26,$F29,0)+$H29/24-$E29/24,OFFSET($D$26,$F29,0)+$H29/24))))) -> 46311 | D29: =IF(OR($B29="",3>$O$10),"",$C29+$E29/24) -> 46311.042 | E29: 1 | F29: 1 | G29: SS | H29: 0 | M29: =IF(OR($Q29="",$R29="",$V29=1),"",($R29-$Q29)*24) | O29: =IF(OR($B29="",3>$O$10),"",IF($AB29=1,"! CHECK LINK",IF($V29=1,"! CHECK DATES",IF($S29=1,IF($R29="","Completed",IF($R29<$D29,"Completed - Ahead",IF($R29<=$D29+1/1440,"Completed - On Time","Completed - Delayed"))),IF($Q29<>"",IF($Y29<=0.1,"In Progress - On Track","In Progress - BEHIND"),IF($M$5<$C29,"Not Started","NOT STARTED - LATE")))))) -> NOT STARTED - LATE | Q29: =IF($I29="","",$I29+IF($J29="",0,$J29)) | R29: =IF($K29="","",$K29+IF($L29="",0,$L29)) | S29: =IF($V29=1,0,IF($R29<>"",1,IF($N29="",0,$N29))) -> 0 | T29: =IF(OR($B29="",$E29=0),0,MEDIAN(0,($M$5-$C29)/($E29/24),1)) -> 1 | U29: =($S29-$T29)*$E29 -> -1 | V29: =IF(OR(AND($Q29<>"",$Q29<$C$8),AND($Q29<>"",$R29<>"",$R29<$Q29),AND($R29<>"",$Q29="")),1,0) -> 0 | W29: =IF($B29="","",IF($S29=1,IF($R29<>"",$R29,$D29),IF($Q29<>"",MAX($M$5,$Q29)+$E29*(1-$S29)/24,MAX($M$5,$C29)+$E29/24))) -> 46311.792 | X29: =IF($B29="","",ROUND(($W29-$D29)*24,1)) -> 18 | Y29: =IF($B29="","",IF($Q29<>"",$X29,IF($X29>0,MAX($X29,IF($Y28="",0,IF($Y28>0,$Y28-MAX(0,($C29-$D28)*24),$Y28))),IF($Y28="",0,IF($Y28>0,$Y28-MAX(0,($C29-$D28)*24),$Y28))))) -> 18 | AB29: =IF(AND($B29<>"",$F29>=3),1,0) -> 0
A30: =IF(OR($B30="",4>$O$10),"",4) -> 4 | B30: Ballast removal | C30: =IF(OR($B30="",4>$O$10),"",IF($F30=0,$C$8,IF($G30="SS",OFFSET($C$26,$F30,0)+$H30/24,IF($G30="FF",OFFSET($D$26,$F30,0)+$H30/24-$E30/24,IF($G30="SF",OFFSET($C$26,$F30,0)+$H30/24-$E30/24,OFFSET($D$26,$F30,0)+$H30/24))))) -> 46311.042 | D30: =IF(OR($B30="",4>$O$10),"",$C30+$E30/24) -> 46311.083 | E30: 1 | F30: 3 | G30: FS | H30: 0 | M30: =IF(OR($Q30="",$R30="",$V30=1),"",($R30-$Q30)*24) | O30: =IF(OR($B30="",4>$O$10),"",IF($AB30=1,"! CHECK LINK",IF($V30=1,"! CHECK DATES",IF($S30=1,IF($R30="","Completed",IF($R30<$D30,"Completed - Ahead",IF($R30<=$D30+1/1440,"Completed - On Time","Completed - Delayed"))),IF($Q30<>"",IF($Y30<=0.1,"In Progress - On Track","In Progress - BEHIND"),IF($M$5<$C30,"Not Started","NOT STARTED - LATE")))))) -> NOT STARTED - LATE | Q30: =IF($I30="","",$I30+IF($J30="",0,$J30)) | R30: =IF($K30="","",$K30+IF($L30="",0,$L30)) | S30: =IF($V30=1,0,IF($R30<>"",1,IF($N30="",0,$N30))) -> 0 | T30: =IF(OR($B30="",$E30=0),0,MEDIAN(0,($M$5-$C30)/($E30/24),1)) -> 1 | U30: =($S30-$T30)*$E30 -> -1 | V30: =IF(OR(AND($Q30<>"",$Q30<$C$8),AND($Q30<>"",$R30<>"",$R30<$Q30),AND($R30<>"",$Q30="")),1,0) -> 0 | W30: =IF($B30="","",IF($S30=1,IF($R30<>"",$R30,$D30),IF($Q30<>"",MAX($M$5,$Q30)+$E30*(1-$S30)/24,MAX($M$5,$C30)+$E30/24))) -> 46311.792 | X30: =IF($B30="","",ROUND(($W30-$D30)*24,1)) -> 17 | Y30: =IF($B30="","",IF($Q30<>"",$X30,IF($X30>0,MAX($X30,IF($Y29="",0,IF($Y29>0,$Y29-MAX(0,($C30-$D29)*24),$Y29))),IF($Y29="",0,IF($Y29>0,$Y29-MAX(0,($C30-$D29)*24),$Y29))))) -> 18 | AB30: =IF(AND($B30<>"",$F30>=4),1,0) -> 0
A31: =IF(OR($B31="",5>$O$10),"",5) -> 5 | B31: Cutting & removal around existing culvert | C31: =IF(OR($B31="",5>$O$10),"",IF($F31=0,$C$8,IF($G31="SS",OFFSET($C$26,$F31,0)+$H31/24,IF($G31="FF",OFFSET($D$26,$F31,0)+$H31/24-$E31/24,IF($G31="SF",OFFSET($C$26,$F31,0)+$H31/24-$E31/24,OFFSET($D$26,$F31,0)+$H31/24))))) -> 46311.083 | D31: =IF(OR($B31="",5>$O$10),"",$C31+$E31/24) -> 46311.208 | E31: 3 | F31: 4 | G31: FS | H31: 0 | M31: =IF(OR($Q31="",$R31="",$V31=1),"",($R31-$Q31)*24) | O31: =IF(OR($B31="",5>$O$10),"",IF($AB31=1,"! CHECK LINK",IF($V31=1,"! CHECK DATES",IF($S31=1,IF($R31="","Completed",IF($R31<$D31,"Completed - Ahead",IF($R31<=$D31+1/1440,"Completed - On Time","Completed - Delayed"))),IF($Q31<>"",IF($Y31<=0.1,"In Progress - On Track","In Progress - BEHIND"),IF($M$5<$C31,"Not Started","NOT STARTED - LATE")))))) -> NOT STARTED - LATE | Q31: =IF($I31="","",$I31+IF($J31="",0,$J31)) | R31: =IF($K31="","",$K31+IF($L31="",0,$L31)) | S31: =IF($V31=1,0,IF($R31<>"",1,IF($N31="",0,$N31))) -> 0 | T31: =IF(OR($B31="",$E31=0),0,MEDIAN(0,($M$5-$C31)/($E31/24),1)) -> 1 | U31: =($S31-$T31)*$E31 -> -3 | V31: =IF(OR(AND($Q31<>"",$Q31<$C$8),AND($Q31<>"",$R31<>"",$R31<$Q31),AND($R31<>"",$Q31="")),1,0) -> 0 | W31: =IF($B31="","",IF($S31=1,IF($R31<>"",$R31,$D31),IF($Q31<>"",MAX($M$5,$Q31)+$E31*(1-$S31)/24,MAX($M$5,$C31)+$E31/24))) -> 46311.875 | X31: =IF($B31="","",ROUND(($W31-$D31)*24,1)) -> 16 | Y31: =IF($B31="","",IF($Q31<>"",$X31,IF($X31>0,MAX($X31,IF($Y30="",0,IF($Y30>0,$Y30-MAX(0,($C31-$D30)*24),$Y30))),IF($Y30="",0,IF($Y30>0,$Y30-MAX(0,($C31-$D30)*24),$Y30))))) -> 18 | AB31: =IF(AND($B31<>"",$F31>=5),1,0) -> 0
A32: =IF(OR($B32="",6>$O$10),"",6) -> 6 | B32: Demolition of existing culvert | C32: =IF(OR($B32="",6>$O$10),"",IF($F32=0,$C$8,IF($G32="SS",OFFSET($C$26,$F32,0)+$H32/24,IF($G32="FF",OFFSET($D$26,$F32,0)+$H32/24-$E32/24,IF($G32="SF",OFFSET($C$26,$F32,0)+$H32/24-$E32/24,OFFSET($D$26,$F32,0)+$H32/24))))) -> 46311.208 | D32: =IF(OR($B32="",6>$O$10),"",$C32+$E32/24) -> 46311.375 | E32: 4 | F32: 5 | G32: FS | H32: 0 | M32: =IF(OR($Q32="",$R32="",$V32=1),"",($R32-$Q32)*24) | O32: =IF(OR($B32="",6>$O$10),"",IF($AB32=1,"! CHECK LINK",IF($V32=1,"! CHECK DATES",IF($S32=1,IF($R32="","Completed",IF($R32<$D32,"Completed - Ahead",IF($R32<=$D32+1/1440,"Completed - On Time","Completed - Delayed"))),IF($Q32<>"",IF($Y32<=0.1,"In Progress - On Track","In Progress - BEHIND"),IF($M$5<$C32,"Not Started","NOT STARTED - LATE")))))) -> NOT STARTED - LATE | Q32: =IF($I32="","",$I32+IF($J32="",0,$J32)) | R32: =IF($K32="","",$K32+IF($L32="",0,$L32)) | S32: =IF($V32=1,0,IF($R32<>"",1,IF($N32="",0,$N32))) -> 0 | T32: =IF(OR($B32="",$E32=0),0,MEDIAN(0,($M$5-$C32)/($E32/24),1)) -> 1 | U32: =($S32-$T32)*$E32 -> -4 | V32: =IF(OR(AND($Q32<>"",$Q32<$C$8),AND($Q32<>"",$R32<>"",$R32<$Q32),AND($R32<>"",$Q32="")),1,0) -> 0 | W32: =IF($B32="","",IF($S32=1,IF($R32<>"",$R32,$D32),IF($Q32<>"",MAX($M$5,$Q32)+$E32*(1-$S32)/24,MAX($M$5,$C32)+$E32/24))) -> 46311.917 | X32: =IF($B32="","",ROUND(($W32-$D32)*24,1)) -> 13 | Y32: =IF($B32="","",IF($Q32<>"",$X32,IF($X32>0,MAX($X32,IF($Y31="",0,IF($Y31>0,$Y31-MAX(0,($C32-$D31)*24),$Y31))),IF($Y31="",0,IF($Y31>0,$Y31-MAX(0,($C32-$D31)*24),$Y31))))) -> 18 | AB32: =IF(AND($B32<>"",$F32>=6),1,0) -> 0
A33: =IF(OR($B33="",7>$O$10),"",7) -> 7 | B33: Surface preparation for precast installation | C33: =IF(OR($B33="",7>$O$10),"",IF($F33=0,$C$8,IF($G33="SS",OFFSET($C$26,$F33,0)+$H33/24,IF($G33="FF",OFFSET($D$26,$F33,0)+$H33/24-$E33/24,IF($G33="SF",OFFSET($C$26,$F33,0)+$H33/24-$E33/24,OFFSET($D$26,$F33,0)+$H33/24))))) -> 46311.375 | D33: =IF(OR($B33="",7>$O$10),"",$C33+$E33/24) -> 46311.458 | E33: 2 | F33: 6 | G33: FS | H33: 0 | M33: =IF(OR($Q33="",$R33="",$V33=1),"",($R33-$Q33)*24) | O33: =IF(OR($B33="",7>$O$10),"",IF($AB33=1,"! CHECK LINK",IF($V33=1,"! CHECK DATES",IF($S33=1,IF($R33="","Completed",IF($R33<$D33,"Completed - Ahead",IF($R33<=$D33+1/1440,"Completed - On Time","Completed - Delayed"))),IF($Q33<>"",IF($Y33<=0.1,"In Progress - On Track","In Progress - BEHIND"),IF($M$5<$C33,"Not Started","NOT STARTED - LATE")))))) -> NOT STARTED - LATE | Q33: =IF($I33="","",$I33+IF($J33="",0,$J33)) | R33: =IF($K33="","",$K33+IF($L33="",0,$L33)) | S33: =IF($V33=1,0,IF($R33<>"",1,IF($N33="",0,$N33))) -> 0 | T33: =IF(OR($B33="",$E33=0),0,MEDIAN(0,($M$5-$C33)/($E33/24),1)) -> 1 | U33: =($S33-$T33)*$E33 -> -2 | V33: =IF(OR(AND($Q33<>"",$Q33<$C$8),AND($Q33<>"",$R33<>"",$R33<$Q33),AND($R33<>"",$Q33="")),1,0) -> 0 | W33: =IF($B33="","",IF($S33=1,IF($R33<>"",$R33,$D33),IF($Q33<>"",MAX($M$5,$Q33)+$E33*(1-$S33)/24,MAX($M$5,$C33)+$E33/24))) -> 46311.833 | X33: =IF($B33="","",ROUND(($W33-$D33)*24,1)) -> 9 | Y33: =IF($B33="","",IF($Q33<>"",$X33,IF($X33>0,MAX($X33,IF($Y32="",0,IF($Y32>0,$Y32-MAX(0,($C33-$D32)*24),$Y32))),IF($Y32="",0,IF($Y32>0,$Y32-MAX(0,($C33-$D32)*24),$Y32))))) -> 18 | AB33: =IF(AND($B33<>"",$F33>=7),1,0) -> 0
A34: =IF(OR($B34="",8>$O$10),"",8) -> 8 | B34: Installation of new precast culvert | C34: =IF(OR($B34="",8>$O$10),"",IF($F34=0,$C$8,IF($G34="SS",OFFSET($C$26,$F34,0)+$H34/24,IF($G34="FF",OFFSET($D$26,$F34,0)+$H34/24-$E34/24,IF($G34="SF",OFFSET($C$26,$F34,0)+$H34/24-$E34/24,OFFSET($D$26,$F34,0)+$H34/24))))) -> 46311.458 | D34: =IF(OR($B34="",8>$O$10),"",$C34+$E34/24) -> 46311.667 | E34: 5 | F34: 7 | G34: FS | H34: 0 | M34: =IF(OR($Q34="",$R34="",$V34=1),"",($R34-$Q34)*24) | O34: =IF(OR($B34="",8>$O$10),"",IF($AB34=1,"! CHECK LINK",IF($V34=1,"! CHECK DATES",IF($S34=1,IF($R34="","Completed",IF($R34<$D34,"Completed - Ahead",IF($R34<=$D34+1/1440,"Completed - On Time","Completed - Delayed"))),IF($Q34<>"",IF($Y34<=0.1,"In Progress - On Track","In Progress - BEHIND"),IF($M$5<$C34,"Not Started","NOT STARTED - LATE")))))) -> NOT STARTED - LATE | Q34: =IF($I34="","",$I34+IF($J34="",0,$J34)) | R34: =IF($K34="","",$K34+IF($L34="",0,$L34)) | S34: =IF($V34=1,0,IF($R34<>"",1,IF($N34="",0,$N34))) -> 0 | T34: =IF(OR($B34="",$E34=0),0,MEDIAN(0,($M$5-$C34)/($E34/24),1)) -> 1 | U34: =($S34-$T34)*$E34 -> -5 | V34: =IF(OR(AND($Q34<>"",$Q34<$C$8),AND($Q34<>"",$R34<>"",$R34<$Q34),AND($R34<>"",$Q34="")),1,0) -> 0 | W34: =IF($B34="","",IF($S34=1,IF($R34<>"",$R34,$D34),IF($Q34<>"",MAX($M$5,$Q34)+$E34*(1-$S34)/24,MAX($M$5,$C34)+$E34/24))) -> 46311.958 | X34: =IF($B34="","",ROUND(($W34-$D34)*24,1)) -> 7 | Y34: =IF($B34="","",IF($Q34<>"",$X34,IF($X34>0,MAX($X34,IF($Y33="",0,IF($Y33>0,$Y33-MAX(0,($C34-$D33)*24),$Y33))),IF($Y33="",0,IF($Y33>0,$Y33-MAX(0,($C34-$D33)*24),$Y33))))) -> 18 | AB34: =IF(AND($B34<>"",$F34>=8),1,0) -> 0
A35: =IF(OR($B35="",9>$O$10),"",9) -> 9 | B35: Apply sealant to the culvert | C35: =IF(OR($B35="",9>$O$10),"",IF($F35=0,$C$8,IF($G35="SS",OFFSET($C$26,$F35,0)+$H35/24,IF($G35="FF",OFFSET($D$26,$F35,0)+$H35/24-$E35/24,IF($G35="SF",OFFSET($C$26,$F35,0)+$H35/24-$E35/24,OFFSET($D$26,$F35,0)+$H35/24))))) -> 46311.667 | D35: =IF(OR($B35="",9>$O$10),"",$C35+$E35/24) -> 46311.75 | E35: 2 | F35: 8 | G35: FS | H35: 0 | M35: =IF(OR($Q35="",$R35="",$V35=1),"",($R35-$Q35)*24) | O35: =IF(OR($B35="",9>$O$10),"",IF($AB35=1,"! CHECK LINK",IF($V35=1,"! CHECK DATES",IF($S35=1,IF($R35="","Completed",IF($R35<$D35,"Completed - Ahead",IF($R35<=$D35+1/1440,"Completed - On Time","Completed - Delayed"))),IF($Q35<>"",IF($Y35<=0.1,"In Progress - On Track","In Progress - BEHIND"),IF($M$5<$C35,"Not Started","NOT STARTED - LATE")))))) -> NOT STARTED - LATE | Q35: =IF($I35="","",$I35+IF($J35="",0,$J35)) | R35: =IF($K35="","",$K35+IF($L35="",0,$L35)) | S35: =IF($V35=1,0,IF($R35<>"",1,IF($N35="",0,$N35))) -> 0 | T35: =IF(OR($B35="",$E35=0),0,MEDIAN(0,($M$5-$C35)/($E35/24),1)) -> 1 | U35: =($S35-$T35)*$E35 -> -2 | V35: =IF(OR(AND($Q35<>"",$Q35<$C$8),AND($Q35<>"",$R35<>"",$R35<$Q35),AND($R35<>"",$Q35="")),1,0) -> 0 | W35: =IF($B35="","",IF($S35=1,IF($R35<>"",$R35,$D35),IF($Q35<>"",MAX($M$5,$Q35)+$E35*(1-$S35)/24,MAX($M$5,$C35)+$E35/24))) -> 46311.833 | X35: =IF($B35="","",ROUND(($W35-$D35)*24,1)) -> 2 | Y35: =IF($B35="","",IF($Q35<>"",$X35,IF($X35>0,MAX($X35,IF($Y34="",0,IF($Y34>0,$Y34-MAX(0,($C35-$D34)*24),$Y34))),IF($Y34="",0,IF($Y34>0,$Y34-MAX(0,($C35-$D34)*24),$Y34))))) -> 18 | AB35: =IF(AND($B35<>"",$F35>=9),1,0) -> 0
A36: =IF(OR($B36="",10>$O$10),"",10) -> 10 | B36: Backfill around culvert to subgrade level | C36: =IF(OR($B36="",10>$O$10),"",IF($F36=0,$C$8,IF($G36="SS",OFFSET($C$26,$F36,0)+$H36/24,IF($G36="FF",OFFSET($D$26,$F36,0)+$H36/24-$E36/24,IF($G36="SF",OFFSET($C$26,$F36,0)+$H36/24-$E36/24,OFFSET($D$26,$F36,0)+$H36/24))))) -> 46311.75 | D36: =IF(OR($B36="",10>$O$10),"",$C36+$E36/24) -> 46311.958 | E36: 5 | F36: 9 | G36: FS | H36: 0 | M36: =IF(OR($Q36="",$R36="",$V36=1),"",($R36-$Q36)*24) | O36: =IF(OR($B36="",10>$O$10),"",IF($AB36=1,"! CHECK LINK",IF($V36=1,"! CHECK DATES",IF($S36=1,IF($R36="","Completed",IF($R36<$D36,"Completed - Ahead",IF($R36<=$D36+1/1440,"Completed - On Time","Completed - Delayed"))),IF($Q36<>"",IF($Y36<=0.1,"In Progress - On Track","In Progress - BEHIND"),IF($M$5<$C36,"Not Started","NOT STARTED - LATE")))))) -> NOT STARTED - LATE | Q36: =IF($I36="","",$I36+IF($J36="",0,$J36)) | R36: =IF($K36="","",$K36+IF($L36="",0,$L36)) | S36: =IF($V36=1,0,IF($R36<>"",1,IF($N36="",0,$N36))) -> 0 | T36: =IF(OR($B36="",$E36=0),0,MEDIAN(0,($M$5-$C36)/($E36/24),1)) -> 0 | U36: =($S36-$T36)*$E36 -> 0 | V36: =IF(OR(AND($Q36<>"",$Q36<$C$8),AND($Q36<>"",$R36<>"",$R36<$Q36),AND($R36<>"",$Q36="")),1,0) -> 0 | W36: =IF($B36="","",IF($S36=1,IF($R36<>"",$R36,$D36),IF($Q36<>"",MAX($M$5,$Q36)+$E36*(1-$S36)/24,MAX($M$5,$C36)+$E36/24))) -> 46311.958 | X36: =IF($B36="","",ROUND(($W36-$D36)*24,1)) -> 0 | Y36: =IF($B36="","",IF($Q36<>"",$X36,IF($X36>0,MAX($X36,IF($Y35="",0,IF($Y35>0,$Y35-MAX(0,($C36-$D35)*24),$Y35))),IF($Y35="",0,IF($Y35>0,$Y35-MAX(0,($C36-$D35)*24),$Y35))))) -> 18 | AB36: =IF(AND($B36<>"",$F36>=10),1,0) -> 0
A37: =IF(OR($B37="",11>$O$10),"",11) -> 11 | B37: Backfill Subgrade | C37: =IF(OR($B37="",11>$O$10),"",IF($F37=0,$C$8,IF($G37="SS",OFFSET($C$26,$F37,0)+$H37/24,IF($G37="FF",OFFSET($D$26,$F37,0)+$H37/24-$E37/24,IF($G37="SF",OFFSET($C$26,$F37,0)+$H37/24-$E37/24,OFFSET($D$26,$F37,0)+$H37/24))))) -> 46311.958 | D37: =IF(OR($B37="",11>$O$10),"",$C37+$E37/24) -> 46312.042 | E37: 2 | F37: 10 | G37: FS | H37: 0 | M37: =IF(OR($Q37="",$R37="",$V37=1),"",($R37-$Q37)*24) | O37: =IF(OR($B37="",11>$O$10),"",IF($AB37=1,"! CHECK LINK",IF($V37=1,"! CHECK DATES",IF($S37=1,IF($R37="","Completed",IF($R37<$D37,"Completed - Ahead",IF($R37<=$D37+1/1440,"Completed - On Time","Completed - Delayed"))),IF($Q37<>"",IF($Y37<=0.1,"In Progress - On Track","In Progress - BEHIND"),IF($M$5<$C37,"Not Started","NOT STARTED - LATE")))))) -> Not Started | Q37: =IF($I37="","",$I37+IF($J37="",0,$J37)) | R37: =IF($K37="","",$K37+IF($L37="",0,$L37)) | S37: =IF($V37=1,0,IF($R37<>"",1,IF($N37="",0,$N37))) -> 0 | T37: =IF(OR($B37="",$E37=0),0,MEDIAN(0,($M$5-$C37)/($E37/24),1)) -> 0 | U37: =($S37-$T37)*$E37 -> 0 | V37: =IF(OR(AND($Q37<>"",$Q37<$C$8),AND($Q37<>"",$R37<>"",$R37<$Q37),AND($R37<>"",$Q37="")),1,0) -> 0 | W37: =IF($B37="","",IF($S37=1,IF($R37<>"",$R37,$D37),IF($Q37<>"",MAX($M$5,$Q37)+$E37*(1-$S37)/24,MAX($M$5,$C37)+$E37/24))) -> 46312.042 | X37: =IF($B37="","",ROUND(($W37-$D37)*24,1)) -> 0 | Y37: =IF($B37="","",IF($Q37<>"",$X37,IF($X37>0,MAX($X37,IF($Y36="",0,IF($Y36>0,$Y36-MAX(0,($C37-$D36)*24),$Y36))),IF($Y36="",0,IF($Y36>0,$Y36-MAX(0,($C37-$D36)*24),$Y36))))) -> 18 | AB37: =IF(AND($B37<>"",$F37>=11),1,0) -> 0
A38: =IF(OR($B38="",12>$O$10),"",12) -> 12 | B38: First layer of ballast (Line 1) | C38: =IF(OR($B38="",12>$O$10),"",IF($F38=0,$C$8,IF($G38="SS",OFFSET($C$26,$F38,0)+$H38/24,IF($G38="FF",OFFSET($D$26,$F38,0)+$H38/24-$E38/24,IF($G38="SF",OFFSET($C$26,$F38,0)+$H38/24-$E38/24,OFFSET($D$26,$F38,0)+$H38/24))))) -> 46312.042 | D38: =IF(OR($B38="",12>$O$10),"",$C38+$E38/24) -> 46312.083 | E38: 1 | F38: 11 | G38: FS | H38: 0 | M38: =IF(OR($Q38="",$R38="",$V38=1),"",($R38-$Q38)*24) | O38: =IF(OR($B38="",12>$O$10),"",IF($AB38=1,"! CHECK LINK",IF($V38=1,"! CHECK DATES",IF($S38=1,IF($R38="","Completed",IF($R38<$D38,"Completed - Ahead",IF($R38<=$D38+1/1440,"Completed - On Time","Completed - Delayed"))),IF($Q38<>"",IF($Y38<=0.1,"In Progress - On Track","In Progress - BEHIND"),IF($M$5<$C38,"Not Started","NOT STARTED - LATE")))))) -> Not Started | Q38: =IF($I38="","",$I38+IF($J38="",0,$J38)) | R38: =IF($K38="","",$K38+IF($L38="",0,$L38)) | S38: =IF($V38=1,0,IF($R38<>"",1,IF($N38="",0,$N38))) -> 0 | T38: =IF(OR($B38="",$E38=0),0,MEDIAN(0,($M$5-$C38)/($E38/24),1)) -> 0 | U38: =($S38-$T38)*$E38 -> 0 | V38: =IF(OR(AND($Q38<>"",$Q38<$C$8),AND($Q38<>"",$R38<>"",$R38<$Q38),AND($R38<>"",$Q38="")),1,0) -> 0 | W38: =IF($B38="","",IF($S38=1,IF($R38<>"",$R38,$D38),IF($Q38<>"",MAX($M$5,$Q38)+$E38*(1-$S38)/24,MAX($M$5,$C38)+$E38/24))) -> 46312.083 | X38: =IF($B38="","",ROUND(($W38-$D38)*24,1)) -> 0 | Y38: =IF($B38="","",IF($Q38<>"",$X38,IF($X38>0,MAX($X38,IF($Y37="",0,IF($Y37>0,$Y37-MAX(0,($C38-$D37)*24),$Y37))),IF($Y37="",0,IF($Y37>0,$Y37-MAX(0,($C38-$D37)*24),$Y37))))) -> 18 | AB38: =IF(AND($B38<>"",$F38>=12),1,0) -> 0
A39: =IF(OR($B39="",13>$O$10),"",13) -> 13 | B39: First layer of ballast (Line 3) | C39: =IF(OR($B39="",13>$O$10),"",IF($F39=0,$C$8,IF($G39="SS",OFFSET($C$26,$F39,0)+$H39/24,IF($G39="FF",OFFSET($D$26,$F39,0)+$H39/24-$E39/24,IF($G39="SF",OFFSET($C$26,$F39,0)+$H39/24-$E39/24,OFFSET($D$26,$F39,0)+$H39/24))))) -> 46312.083 | D39: =IF(OR($B39="",13>$O$10),"",$C39+$E39/24) -> 46312.125 | E39: 1 | F39: 12 | G39: FS | H39: 0 | M39: =IF(OR($Q39="",$R39="",$V39=1),"",($R39-$Q39)*24) | O39: =IF(OR($B39="",13>$O$10),"",IF($AB39=1,"! CHECK LINK",IF($V39=1,"! CHECK DATES",IF($S39=1,IF($R39="","Completed",IF($R39<$D39,"Completed - Ahead",IF($R39<=$D39+1/1440,"Completed - On Time","Completed - Delayed"))),IF($Q39<>"",IF($Y39<=0.1,"In Progress - On Track","In Progress - BEHIND"),IF($M$5<$C39,"Not Started","NOT STARTED - LATE")))))) -> Not Started | Q39: =IF($I39="","",$I39+IF($J39="",0,$J39)) | R39: =IF($K39="","",$K39+IF($L39="",0,$L39)) | S39: =IF($V39=1,0,IF($R39<>"",1,IF($N39="",0,$N39))) -> 0 | T39: =IF(OR($B39="",$E39=0),0,MEDIAN(0,($M$5-$C39)/($E39/24),1)) -> 0 | U39: =($S39-$T39)*$E39 -> 0 | V39: =IF(OR(AND($Q39<>"",$Q39<$C$8),AND($Q39<>"",$R39<>"",$R39<$Q39),AND($R39<>"",$Q39="")),1,0) -> 0 | W39: =IF($B39="","",IF($S39=1,IF($R39<>"",$R39,$D39),IF($Q39<>"",MAX($M$5,$Q39)+$E39*(1-$S39)/24,MAX($M$5,$C39)+$E39/24))) -> 46312.125 | X39: =IF($B39="","",ROUND(($W39-$D39)*24,1)) -> 0 | Y39: =IF($B39="","",IF($Q39<>"",$X39,IF($X39>0,MAX($X39,IF($Y38="",0,IF($Y38>0,$Y38-MAX(0,($C39-$D38)*24),$Y38))),IF($Y38="",0,IF($Y38>0,$Y38-MAX(0,($C39-$D38)*24),$Y38))))) -> 18 | AB39: =IF(AND($B39<>"",$F39>=13),1,0) -> 0
A40: =IF(OR($B40="",14>$O$10),"",14) -> 14 | B40: Track installation (Line 1) | C40: =IF(OR($B40="",14>$O$10),"",IF($F40=0,$C$8,IF($G40="SS",OFFSET($C$26,$F40,0)+$H40/24,IF($G40="FF",OFFSET($D$26,$F40,0)+$H40/24-$E40/24,IF($G40="SF",OFFSET($C$26,$F40,0)+$H40/24-$E40/24,OFFSET($D$26,$F40,0)+$H40/24))))) -> 46312.125 | D40: =IF(OR($B40="",14>$O$10),"",$C40+$E40/24) -> 46312.167 | E40: 1 | F40: 13 | G40: FS | H40: 0 | M40: =IF(OR($Q40="",$R40="",$V40=1),"",($R40-$Q40)*24) | O40: =IF(OR($B40="",14>$O$10),"",IF($AB40=1,"! CHECK LINK",IF($V40=1,"! CHECK DATES",IF($S40=1,IF($R40="","Completed",IF($R40<$D40,"Completed - Ahead",IF($R40<=$D40+1/1440,"Completed - On Time","Completed - Delayed"))),IF($Q40<>"",IF($Y40<=0.1,"In Progress - On Track","In Progress - BEHIND"),IF($M$5<$C40,"Not Started","NOT STARTED - LATE")))))) -> Not Started | Q40: =IF($I40="","",$I40+IF($J40="",0,$J40)) | R40: =IF($K40="","",$K40+IF($L40="",0,$L40)) | S40: =IF($V40=1,0,IF($R40<>"",1,IF($N40="",0,$N40))) -> 0 | T40: =IF(OR($B40="",$E40=0),0,MEDIAN(0,($M$5-$C40)/($E40/24),1)) -> 0 | U40: =($S40-$T40)*$E40 -> 0 | V40: =IF(OR(AND($Q40<>"",$Q40<$C$8),AND($Q40<>"",$R40<>"",$R40<$Q40),AND($R40<>"",$Q40="")),1,0) -> 0 | W40: =IF($B40="","",IF($S40=1,IF($R40<>"",$R40,$D40),IF($Q40<>"",MAX($M$5,$Q40)+$E40*(1-$S40)/24,MAX($M$5,$C40)+$E40/24))) -> 46312.167 | X40: =IF($B40="","",ROUND(($W40-$D40)*24,1)) -> 0 | Y40: =IF($B40="","",IF($Q40<>"",$X40,IF($X40>0,MAX($X40,IF($Y39="",0,IF($Y39>0,$Y39-MAX(0,($C40-$D39)*24),$Y39))),IF($Y39="",0,IF($Y39>0,$Y39-MAX(0,($C40-$D39)*24),$Y39))))) -> 18 | AB40: =IF(AND($B40<>"",$F40>=14),1,0) -> 0
A41: =IF(OR($B41="",15>$O$10),"",15) -> 15 | B41: Track installation (Line 3) | C41: =IF(OR($B41="",15>$O$10),"",IF($F41=0,$C$8,IF($G41="SS",OFFSET($C$26,$F41,0)+$H41/24,IF($G41="FF",OFFSET($D$26,$F41,0)+$H41/24-$E41/24,IF($G41="SF",OFFSET($C$26,$F41,0)+$H41/24-$E41/24,OFFSET($D$26,$F41,0)+$H41/24))))) -> 46312.167 | D41: =IF(OR($B41="",15>$O$10),"",$C41+$E41/24) -> 46312.208 | E41: 1 | F41: 14 | G41: FS | H41: 0 | M41: =IF(OR($Q41="",$R41="",$V41=1),"",($R41-$Q41)*24) | O41: =IF(OR($B41="",15>$O$10),"",IF($AB41=1,"! CHECK LINK",IF($V41=1,"! CHECK DATES",IF($S41=1,IF($R41="","Completed",IF($R41<$D41,"Completed - Ahead",IF($R41<=$D41+1/1440,"Completed - On Time","Completed - Delayed"))),IF($Q41<>"",IF($Y41<=0.1,"In Progress - On Track","In Progress - BEHIND"),IF($M$5<$C41,"Not Started","NOT STARTED - LATE")))))) -> Not Started | Q41: =IF($I41="","",$I41+IF($J41="",0,$J41)) | R41: =IF($K41="","",$K41+IF($L41="",0,$L41)) | S41: =IF($V41=1,0,IF($R41<>"",1,IF($N41="",0,$N41))) -> 0 | T41: =IF(OR($B41="",$E41=0),0,MEDIAN(0,($M$5-$C41)/($E41/24),1)) -> 0 | U41: =($S41-$T41)*$E41 -> 0 | V41: =IF(OR(AND($Q41<>"",$Q41<$C$8),AND($Q41<>"",$R41<>"",$R41<$Q41),AND($R41<>"",$Q41="")),1,0) -> 0 | W41: =IF($B41="","",IF($S41=1,IF($R41<>"",$R41,$D41),IF($Q41<>"",MAX($M$5,$Q41)+$E41*(1-$S41)/24,MAX($M$5,$C41)+$E41/24))) -> 46312.208 | X41: =IF($B41="","",ROUND(($W41-$D41)*24,1)) -> 0 | Y41: =IF($B41="","",IF($Q41<>"",$X41,IF($X41>0,MAX($X41,IF($Y40="",0,IF($Y40>0,$Y40-MAX(0,($C41-$D40)*24),$Y40))),IF($Y40="",0,IF($Y40>0,$Y40-MAX(0,($C41-$D40)*24),$Y40))))) -> 18 | AB41: =IF(AND($B41<>"",$F41>=15),1,0) -> 0
A42: =IF(OR($B42="",16>$O$10),"",16) -> 16 | B42: 1st & 2nd Ballasting / Tamping (Line 1) | C42: =IF(OR($B42="",16>$O$10),"",IF($F42=0,$C$8,IF($G42="SS",OFFSET($C$26,$F42,0)+$H42/24,IF($G42="FF",OFFSET($D$26,$F42,0)+$H42/24-$E42/24,IF($G42="SF",OFFSET($C$26,$F42,0)+$H42/24-$E42/24,OFFSET($D$26,$F42,0)+$H42/24))))) -> 46312.208 | D42: =IF(OR($B42="",16>$O$10),"",$C42+$E42/24) -> 46312.25 | E42: 1 | F42: 15 | G42: FS | H42: 0 | M42: =IF(OR($Q42="",$R42="",$V42=1),"",($R42-$Q42)*24) | O42: =IF(OR($B42="",16>$O$10),"",IF($AB42=1,"! CHECK LINK",IF($V42=1,"! CHECK DATES",IF($S42=1,IF($R42="","Completed",IF($R42<$D42,"Completed - Ahead",IF($R42<=$D42+1/1440,"Completed - On Time","Completed - Delayed"))),IF($Q42<>"",IF($Y42<=0.1,"In Progress - On Track","In Progress - BEHIND"),IF($M$5<$C42,"Not Started","NOT STARTED - LATE")))))) -> Not Started | Q42: =IF($I42="","",$I42+IF($J42="",0,$J42)) | R42: =IF($K42="","",$K42+IF($L42="",0,$L42)) | S42: =IF($V42=1,0,IF($R42<>"",1,IF($N42="",0,$N42))) -> 0 | T42: =IF(OR($B42="",$E42=0),0,MEDIAN(0,($M$5-$C42)/($E42/24),1)) -> 0 | U42: =($S42-$T42)*$E42 -> 0 | V42: =IF(OR(AND($Q42<>"",$Q42<$C$8),AND($Q42<>"",$R42<>"",$R42<$Q42),AND($R42<>"",$Q42="")),1,0) -> 0 | W42: =IF($B42="","",IF($S42=1,IF($R42<>"",$R42,$D42),IF($Q42<>"",MAX($M$5,$Q42)+$E42*(1-$S42)/24,MAX($M$5,$C42)+$E42/24))) -> 46312.25 | X42: =IF($B42="","",ROUND(($W42-$D42)*24,1)) -> 0 | Y42: =IF($B42="","",IF($Q42<>"",$X42,IF($X42>0,MAX($X42,IF($Y41="",0,IF($Y41>0,$Y41-MAX(0,($C42-$D41)*24),$Y41))),IF($Y41="",0,IF($Y41>0,$Y41-MAX(0,($C42-$D41)*24),$Y41))))) -> 18 | AB42: =IF(AND($B42<>"",$F42>=16),1,0) -> 0
A43: =IF(OR($B43="",17>$O$10),"",17) -> 17 | B43: Final Ballasting / Tamping (Line 1) | C43: =IF(OR($B43="",17>$O$10),"",IF($F43=0,$C$8,IF($G43="SS",OFFSET($C$26,$F43,0)+$H43/24,IF($G43="FF",OFFSET($D$26,$F43,0)+$H43/24-$E43/24,IF($G43="SF",OFFSET($C$26,$F43,0)+$H43/24-$E43/24,OFFSET($D$26,$F43,0)+$H43/24))))) -> 46312.25 | D43: =IF(OR($B43="",17>$O$10),"",$C43+$E43/24) -> 46312.292 | E43: 1 | F43: 16 | G43: FS | H43: 0 | M43: =IF(OR($Q43="",$R43="",$V43=1),"",($R43-$Q43)*24) | O43: =IF(OR($B43="",17>$O$10),"",IF($AB43=1,"! CHECK LINK",IF($V43=1,"! CHECK DATES",IF($S43=1,IF($R43="","Completed",IF($R43<$D43,"Completed - Ahead",IF($R43<=$D43+1/1440,"Completed - On Time","Completed - Delayed"))),IF($Q43<>"",IF($Y43<=0.1,"In Progress - On Track","In Progress - BEHIND"),IF($M$5<$C43,"Not Started","NOT STARTED - LATE")))))) -> Not Started | Q43: =IF($I43="","",$I43+IF($J43="",0,$J43)) | R43: =IF($K43="","",$K43+IF($L43="",0,$L43)) | S43: =IF($V43=1,0,IF($R43<>"",1,IF($N43="",0,$N43))) -> 0 | T43: =IF(OR($B43="",$E43=0),0,MEDIAN(0,($M$5-$C43)/($E43/24),1)) -> 0 | U43: =($S43-$T43)*$E43 -> 0 | V43: =IF(OR(AND($Q43<>"",$Q43<$C$8),AND($Q43<>"",$R43<>"",$R43<$Q43),AND($R43<>"",$Q43="")),1,0) -> 0 | W43: =IF($B43="","",IF($S43=1,IF($R43<>"",$R43,$D43),IF($Q43<>"",MAX($M$5,$Q43)+$E43*(1-$S43)/24,MAX($M$5,$C43)+$E43/24))) -> 46312.292 | X43: =IF($B43="","",ROUND(($W43-$D43)*24,1)) -> 0 | Y43: =IF($B43="","",IF($Q43<>"",$X43,IF($X43>0,MAX($X43,IF($Y42="",0,IF($Y42>0,$Y42-MAX(0,($C43-$D42)*24),$Y42))),IF($Y42="",0,IF($Y42>0,$Y42-MAX(0,($C43-$D42)*24),$Y42))))) -> 18 | AB43: =IF(AND($B43<>"",$F43>=17),1,0) -> 0
A44: =IF(OR($B44="",18>$O$10),"",18) -> 18 | B44: OTMP moves from line 1 to Line 3 TK 121+000 | C44: =IF(OR($B44="",18>$O$10),"",IF($F44=0,$C$8,IF($G44="SS",OFFSET($C$26,$F44,0)+$H44/24,IF($G44="FF",OFFSET($D$26,$F44,0)+$H44/24-$E44/24,IF($G44="SF",OFFSET($C$26,$F44,0)+$H44/24-$E44/24,OFFSET($D$26,$F44,0)+$H44/24))))) -> 46312.292 | D44: =IF(OR($B44="",18>$O$10),"",$C44+$E44/24) -> 46312.333 | E44: 1 | F44: 17 | G44: FS | H44: 0 | M44: =IF(OR($Q44="",$R44="",$V44=1),"",($R44-$Q44)*24) | O44: =IF(OR($B44="",18>$O$10),"",IF($AB44=1,"! CHECK LINK",IF($V44=1,"! CHECK DATES",IF($S44=1,IF($R44="","Completed",IF($R44<$D44,"Completed - Ahead",IF($R44<=$D44+1/1440,"Completed - On Time","Completed - Delayed"))),IF($Q44<>"",IF($Y44<=0.1,"In Progress - On Track","In Progress - BEHIND"),IF($M$5<$C44,"Not Started","NOT STARTED - LATE")))))) -> Not Started | Q44: =IF($I44="","",$I44+IF($J44="",0,$J44)) | R44: =IF($K44="","",$K44+IF($L44="",0,$L44)) | S44: =IF($V44=1,0,IF($R44<>"",1,IF($N44="",0,$N44))) -> 0 | T44: =IF(OR($B44="",$E44=0),0,MEDIAN(0,($M$5-$C44)/($E44/24),1)) -> 0 | U44: =($S44-$T44)*$E44 -> 0 | V44: =IF(OR(AND($Q44<>"",$Q44<$C$8),AND($Q44<>"",$R44<>"",$R44<$Q44),AND($R44<>"",$Q44="")),1,0) -> 0 | W44: =IF($B44="","",IF($S44=1,IF($R44<>"",$R44,$D44),IF($Q44<>"",MAX($M$5,$Q44)+$E44*(1-$S44)/24,MAX($M$5,$C44)+$E44/24))) -> 46312.333 | X44: =IF($B44="","",ROUND(($W44-$D44)*24,1)) -> 0 | Y44: =IF($B44="","",IF($Q44<>"",$X44,IF($X44>0,MAX($X44,IF($Y43="",0,IF($Y43>0,$Y43-MAX(0,($C44-$D43)*24),$Y43))),IF($Y43="",0,IF($Y43>0,$Y43-MAX(0,($C44-$D43)*24),$Y43))))) -> 18 | AB44: =IF(AND($B44<>"",$F44>=18),1,0) -> 0
A45: =IF(OR($B45="",19>$O$10),"",19) -> 19 | B45: ATW – 2U (out of destressing) (Line 1) | C45: =IF(OR($B45="",19>$O$10),"",IF($F45=0,$C$8,IF($G45="SS",OFFSET($C$26,$F45,0)+$H45/24,IF($G45="FF",OFFSET($D$26,$F45,0)+$H45/24-$E45/24,IF($G45="SF",OFFSET($C$26,$F45,0)+$H45/24-$E45/24,OFFSET($D$26,$F45,0)+$H45/24))))) -> 46312.333 | D45: =IF(OR($B45="",19>$O$10),"",$C45+$E45/24) -> 46312.417 | E45: 2 | F45: 18 | G45: FS | H45: 0 | M45: =IF(OR($Q45="",$R45="",$V45=1),"",($R45-$Q45)*24) | O45: =IF(OR($B45="",19>$O$10),"",IF($AB45=1,"! CHECK LINK",IF($V45=1,"! CHECK DATES",IF($S45=1,IF($R45="","Completed",IF($R45<$D45,"Completed - Ahead",IF($R45<=$D45+1/1440,"Completed - On Time","Completed - Delayed"))),IF($Q45<>"",IF($Y45<=0.1,"In Progress - On Track","In Progress - BEHIND"),IF($M$5<$C45,"Not Started","NOT STARTED - LATE")))))) -> Not Started | Q45: =IF($I45="","",$I45+IF($J45="",0,$J45)) | R45: =IF($K45="","",$K45+IF($L45="",0,$L45)) | S45: =IF($V45=1,0,IF($R45<>"",1,IF($N45="",0,$N45))) -> 0 | T45: =IF(OR($B45="",$E45=0),0,MEDIAN(0,($M$5-$C45)/($E45/24),1)) -> 0 | U45: =($S45-$T45)*$E45 -> 0 | V45: =IF(OR(AND($Q45<>"",$Q45<$C$8),AND($Q45<>"",$R45<>"",$R45<$Q45),AND($R45<>"",$Q45="")),1,0) -> 0 | W45: =IF($B45="","",IF($S45=1,IF($R45<>"",$R45,$D45),IF($Q45<>"",MAX($M$5,$Q45)+$E45*(1-$S45)/24,MAX($M$5,$C45)+$E45/24))) -> 46312.417 | X45: =IF($B45="","",ROUND(($W45-$D45)*24,1)) -> 0 | Y45: =IF($B45="","",IF($Q45<>"",$X45,IF($X45>0,MAX($X45,IF($Y44="",0,IF($Y44>0,$Y44-MAX(0,($C45-$D44)*24),$Y44))),IF($Y44="",0,IF($Y44>0,$Y44-MAX(0,($C45-$D44)*24),$Y44))))) -> 18 | AB45: =IF(AND($B45<>"",$F45>=19),1,0) -> 0
A46: =IF(OR($B46="",20>$O$10),"",20) -> 20 | B46: ATW – 2U (out of destressing) (Line 3) | C46: =IF(OR($B46="",20>$O$10),"",IF($F46=0,$C$8,IF($G46="SS",OFFSET($C$26,$F46,0)+$H46/24,IF($G46="FF",OFFSET($D$26,$F46,0)+$H46/24-$E46/24,IF($G46="SF",OFFSET($C$26,$F46,0)+$H46/24-$E46/24,OFFSET($D$26,$F46,0)+$H46/24))))) -> 46312.417 | D46: =IF(OR($B46="",20>$O$10),"",$C46+$E46/24) -> 46312.5 | E46: 2 | F46: 19 | G46: FS | H46: 0 | M46: =IF(OR($Q46="",$R46="",$V46=1),"",($R46-$Q46)*24) | O46: =IF(OR($B46="",20>$O$10),"",IF($AB46=1,"! CHECK LINK",IF($V46=1,"! CHECK DATES",IF($S46=1,IF($R46="","Completed",IF($R46<$D46,"Completed - Ahead",IF($R46<=$D46+1/1440,"Completed - On Time","Completed - Delayed"))),IF($Q46<>"",IF($Y46<=0.1,"In Progress - On Track","In Progress - BEHIND"),IF($M$5<$C46,"Not Started","NOT STARTED - LATE")))))) -> Not Started | Q46: =IF($I46="","",$I46+IF($J46="",0,$J46)) | R46: =IF($K46="","",$K46+IF($L46="",0,$L46)) | S46: =IF($V46=1,0,IF($R46<>"",1,IF($N46="",0,$N46))) -> 0 | T46: =IF(OR($B46="",$E46=0),0,MEDIAN(0,($M$5-$C46)/($E46/24),1)) -> 0 | U46: =($S46-$T46)*$E46 -> 0 | V46: =IF(OR(AND($Q46<>"",$Q46<$C$8),AND($Q46<>"",$R46<>"",$R46<$Q46),AND($R46<>"",$Q46="")),1,0) -> 0 | W46: =IF($B46="","",IF($S46=1,IF($R46<>"",$R46,$D46),IF($Q46<>"",MAX($M$5,$Q46)+$E46*(1-$S46)/24,MAX($M$5,$C46)+$E46/24))) -> 46312.5 | X46: =IF($B46="","",ROUND(($W46-$D46)*24,1)) -> 0 | Y46: =IF($B46="","",IF($Q46<>"",$X46,IF($X46>0,MAX($X46,IF($Y45="",0,IF($Y45>0,$Y45-MAX(0,($C46-$D45)*24),$Y45))),IF($Y45="",0,IF($Y45>0,$Y45-MAX(0,($C46-$D45)*24),$Y45))))) -> 18 | AB46: =IF(AND($B46<>"",$F46>=20),1,0) -> 0
...
