Workbook

Sheet Cover
A4: SAR | I4: SAUDI ARABIA RAILWAYS
I5: Project Controls | East West Railway
A8: EAST WEST RAILWAY (EWR) | CULVERTS REPLACEMENT PHASE 2
A9: SHUTDOWN 02 - PROGRESS REPORT
A10: Culverts C028, C052, C053, C067 and C070 | August 2026
A13: SHUTDOWN START | E13: SHUTDOWN FINISH | I13: PLANNED DURATION | O13: WORK LOCATIONS
A14: 21-Aug-2026 | E14: 22-Aug-2026 | I14: 2 days | O14: 5 culverts
A15: 00:00 | E15: 00:00 | I15: per activity plan | O15: KM 116+700 - 132+198
A44: NOTE FOR RECONCILIATION
A45: Header finish reads 22-Aug-2026 00:00 while the activity plan runs to 23-Aug-2026.
A46: Waiting locations read TK 121+000 / TK 131+000 here and TK 120+000 / TK 130+000 in the OTMP narrative.
A48: DOCUMENT CONTROL
A49: DOCUMENT REF. | E49: REVISION | I49: DATE | O49: STATUS
A52: PREPARED BY | E52: CHECKED BY | I52: APPROVED BY | O52: CLIENT / SAR
A54: Name / Signature / Date | E54: Name / Signature / Date | I54: Name / Signature / Date | O54: Name / Signature / Date
A56: Culverts Replacement Phase 2 - EWR | Shutdown 02 Progress Report | I56: Page 1 of 1 - Cover
A57: SAUDI ARABIA RAILWAYS | SAR.COM.SA

Sheet Shutdown02 Progress
A1: EWR CULVERTS REPLACEMENT PHASE 2 - SHUTDOWN 03 PROGRESS TRACKER
A2: AUGUST 2026 | Culverts: C263, C265, C267, C288, C289
A4: =NOW() -> 46305.345 | C4: Start : 16-Oct-2026 00.00 AM | J4: Finish : 17-Oct-2026 00.00 AM | O4: Time Remaining : | R4: =V13 -> 7day15hrs41mins
V5: 46311.999 | Y5: Day 2 (00:00): | Z5: 46312.999
V9: =NOW() -> 46305.345
V13: =INT(Z5-V9)&"day"&TEXT(Z5-V9,"h""hrs""m""mins""") -> 7day15hrs41mins
U14: =IF(OR(B2="",G2=""),"",IF(G2<B2,"Ahead",IF(G2=B2,"On-Time","Delayed")))
A15: No | B15: Work Description | C15: No. Hours | D15: Wt. %P | E15: Wt.%PA | G15: Date (Plan) | I15: Date (Actual | K15: Time (Plan-Target) | M15: Total Time (Plan) | N15: Time (vs. Actual) | P15: Total Time Completed | Q15: Time Difference (Ahead, On-Time, Delayed) | R15: Progress Status | S15: Remarks
F16: % Progress | G16: Start | H16: End | I16: Start | J16: End | K16: Start | L16: End | N16: Start | O16: End
V17: Completed - Ahead of time
A18: LOCATION: C263 , TK 209+025 (Line 1 & Line 3) | V18: Completed
A19: 1 | B19: Pre-Shutdown Arrangement (Mobilization Works) | C19: T-48 Hours | R19: =IF(F19=100%,"Completed",IF(F19=0,"Not Started","In Progress")) -> Not Started | V19: Completed - Delayed
A20: =A19+1 -> 2 | B20: TSO OTMP moves from station 29 to Main Line 1 | C20: =1/24 -> 0.041666667 | D20: 2.03 | E20: =D20*F20 -> 0 | G20: 46311 | H20: 46311 | K20: 0 | L20: =K20+C20 -> 0.041666667 | M20: =L20-K20 -> 0.041666667 | P20: =IF(OR(I20="",J20="",N20="",O20=""),"",((J20+O20)-(I20+N20))) | Q20: =IF(OR(H20="",J20="",L20="",O20=""),"",IF((J20+O20)<(H20+L20),"Ahead",IF((J20+O20)=(H20+L20),"On-Time","Delayed"))) | R20: =IF(F20=100%,"Completed",IF(F20=0,"Not Started","In Progress")) -> Not Started | S20: OTMP Movement
A21: 3 | B21: Track removal and evacuation of panels (line 1) | C21: =1/24 -> 0.041666667 | D21: =(C21/$C$47)*100 -> 2.0408163 | E21: =D21*F21 -> 0 | G21: 46311 | H21: 46311 | K21: 0.041666667 | L21: 0.083333333 | M21: =L21-K21 -> 0.041666667 | P21: =IF(OR(I21="",J21="",N21="",O21=""),"",((J21+O21)-(I21+N21))) | Q21: =IF(OR(H21="",J21="",L21="",O21=""),"",IF((J21+O21)<(H21+L21),"Ahead",IF((J21+O21)=(H21+L21),"On-Time","Delayed"))) | R21: =IF(F21=100%,"Completed",IF(F21=0,"Not Started","In Progress")) -> Not Started | V21: In-progress
A22: =A21+1 -> 4 | B22: Track removal and evacuation of panels (line 3) | C22: 0.041666667 | D22: =(C22/$C$47)*100 -> 2.0408163 | E22: =D22*F22 -> 0 | G22: 46311 | H22: 46311 | K22: 0 | L22: 0.041666667 | M22: =L22-K22 -> 0.041666667 | P22: =IF(OR(I22="",J22="",N22="",O22=""),"",((J22+O22)-(I22+N22))) | Q22: =IF(OR(H22="",J22="",L22="",O22=""),"",IF((J22+O22)<(H22+L22),"Ahead",IF((J22+O22)=(H22+L22),"On-Time","Delayed"))) | R22: =IF(F22=100%,"Completed",IF(F22=0,"Not Started","In Progress")) -> Not Started
A23: =A22+1 -> 5 | B23: Ballast removal | C23: =1/24 -> 0.041666667 | D23: =(C23/$C$47)*100 -> 2.0408163 | E23: =D23*F23 -> 0 | G23: 46311 | H23: 46311 | K23: =L21 -> 0.083333333 | L23: =K23+C23 -> 0.125 | M23: =L23-K23 -> 0.041666667 | P23: =IF(OR(I23="",J23="",N23="",O23=""),"",((J23+O23)-(I23+N23))) | Q23: =IF(OR(H23="",J23="",L23="",O23=""),"",IF((J23+O23)<(H23+L23),"Ahead",IF((J23+O23)=(H23+L23),"On-Time","Delayed"))) | R23: =IF(F23=100%,"Completed",IF(F23=0,"Not Started","In Progress")) -> Not Started | V23: Completed - Ontime
A24: =A23+1 -> 6 | B24: Cutting and removal of material around existing culvert | C24: =3/24 -> 0.125 | D24: =(C24/$C$47)*100 -> 6.122449 | E24: =D24*F24 -> 0 | G24: 46311 | H24: 46311 | K24: =L23 -> 0.125 | L24: =K24+C24 -> 0.25 | M24: =L24-K24 -> 0.125 | P24: =IF(OR(I24="",J24="",N24="",O24=""),"",((J24+O24)-(I24+N24))) | Q24: =IF(OR(H24="",J24="",L24="",O24=""),"",IF((J24+O24)<(H24+L24),"Ahead",IF((J24+O24)=(H24+L24),"On-Time","Delayed"))) | R24: =IF(F24=100%,"Completed",IF(F24=0,"Not Started","In Progress")) -> Not Started
A25: =A24+1 -> 7 | B25: Demolition of existing culvert | C25: =4/24 -> 0.16666667 | D25: =(C25/$C$47)*100 -> 8.1632653 | E25: =D25*F25 -> 0 | G25: 46311 | H25: 46311 | K25: =L24 -> 0.25 | L25: =K25+C25 -> 0.41666667 | M25: =L25-K25 -> 0.16666667 | P25: =IF(OR(I25="",J25="",N25="",O25=""),"",((J25+O25)-(I25+N25))) | Q25: =IF(OR(H25="",J25="",L25="",O25=""),"",IF((J25+O25)<(H25+L25),"Ahead",IF((J25+O25)=(H25+L25),"On-Time","Delayed"))) | R25: =IF(F25=100%,"Completed",IF(F25=0,"Not Started","In Progress")) -> Not Started
A26: =A25+1 -> 8 | B26: Surface preparation for the precast culvert installation | C26: =2/24 -> 0.083333333 | D26: =(C26/$C$47)*100 -> 4.0816327 | E26: =D26*F26 -> 0 | G26: 46311 | H26: 46311 | K26: =L25 -> 0.41666667 | L26: =K26+C26 -> 0.5 | M26: =L26-K26 -> 0.083333333 | P26: =IF(OR(I26="",J26="",N26="",O26=""),"",((J26+O26)-(I26+N26))) | Q26: =IF(OR(H26="",J26="",L26="",O26=""),"",IF((J26+O26)<(H26+L26),"Ahead",IF((J26+O26)=(H26+L26),"On-Time","Delayed"))) | R26: =IF(F26=100%,"Completed",IF(F26=0,"Not Started","In Progress")) -> Not Started
A27: =A26+1 -> 9 | B27: Installation of new precast culvert | C27: =5/24 -> 0.20833333 | D27: =(C27/$C$47)*100 -> 10.204082 | E27: =D27*F27 -> 0 | G27: 46311 | H27: 46311 | K27: =L26 -> 0.5 | L27: =K27+C27 -> 0.70833333 | M27: =L27-K27 -> 0.20833333 | P27: =IF(OR(I27="",J27="",N27="",O27=""),"",((J27+O27)-(I27+N27))) | Q27: =IF(OR(H27="",J27="",L27="",O27=""),"",IF((J27+O27)<(H27+L27),"Ahead",IF((J27+O27)=(H27+L27),"On-Time","Delayed"))) | R27: =IF(F27=100%,"Completed",IF(F27=0,"Not Started","In Progress")) -> Not Started
A28: =A27+1 -> 10 | B28: Apply sealant to the culvert | C28: =2/24 -> 0.083333333 | D28: =(C28/$C$47)*100 -> 4.0816327 | E28: =D28*F28 -> 0 | G28: 46311 | H28: 46311 | K28: =L27 -> 0.70833333 | L28: =K28+C28 -> 0.79166667 | M28: =L28-K28 -> 0.083333333 | P28: =IF(OR(I28="",J28="",N28="",O28=""),"",((J28+O28)-(I28+N28))) | Q28: =IF(OR(H28="",J28="",L28="",O28=""),"",IF((J28+O28)<(H28+L28),"Ahead",IF((J28+O28)=(H28+L28),"On-Time","Delayed"))) | R28: =IF(F28=100%,"Completed",IF(F28=0,"Not Started","In Progress")) -> Not Started
A29: =A28+1 -> 11 | B29: Backfill around the culvert till subgrade level | C29: =5/24 -> 0.20833333 | D29: =(C29/$C$47)*100 -> 10.204082 | E29: =D29*F29 -> 0 | G29: 46311 | H29: 46311 | K29: =L28 -> 0.79166667 | L29: =K29+C29 -> 1 | M29: =L29-K29 -> 0.20833333 | P29: =IF(OR(I29="",J29="",N29="",O29=""),"",((J29+O29)-(I29+N29))) | Q29: =IF(OR(H29="",J29="",L29="",O29=""),"",IF((J29+O29)<(H29+L29),"Ahead",IF((J29+O29)=(H29+L29),"On-Time","Delayed"))) | R29: =IF(F29=100%,"Completed",IF(F29=0,"Not Started","In Progress")) -> Not Started
A30: =A29+1 -> 12 | B30: Backfill Subgrade | C30: =2/24 -> 0.083333333 | D30: =(C30/$C$47)*100 -> 4.0816327 | E30: =D30*F30 -> 0 | G30: 46312 | H30: 46312 | K30: =L29 -> 1 | L30: =K30+C30 -> 1.0833333 | M30: =L30-K30 -> 0.083333333 | P30: =IF(OR(I30="",J30="",N30="",O30=""),"",((J30+O30)-(I30+N30))) | Q30: =IF(OR(H30="",J30="",L30="",O30=""),"",IF((J30+O30)<(H30+L30),"Ahead",IF((J30+O30)=(H30+L30),"On-Time","Delayed"))) | R30: =IF(F30=100%,"Completed",IF(F30=0,"Not Started","In Progress")) -> Not Started
A31: =A30+1 -> 13 | B31: First layer of ballast (line 1) | C31: =1/24 -> 0.041666667 | D31: =(C31/$C$47)*100 -> 2.0408163 | E31: =D31*F31 -> 0 | G31: 46312 | H31: 46312 | K31: =L30 -> 1.0833333 | L31: =K31+C31 -> 1.125 | M31: =L31-K31 -> 0.041666667 | P31: =IF(OR(I31="",J31="",N31="",O31=""),"",((J31+O31)-(I31+N31))) | Q31: =IF(OR(H31="",J31="",L31="",O31=""),"",IF((J31+O31)<(H31+L31),"Ahead",IF((J31+O31)=(H31+L31),"On-Time","Delayed"))) | R31: =IF(F31=100%,"Completed",IF(F31=0,"Not Started","In Progress")) -> Not Started
A32: =A31+1 -> 14 | B32: First layer of ballast (line 3) | C32: =1/24 -> 0.041666667 | D32: =(C32/$C$47)*100 -> 2.0408163 | E32: =D32*F32 -> 0 | G32: 46312 | H32: 46312 | K32: =L31 -> 1.125 | L32: =K32+C32 -> 1.1666667 | M32: =L32-K32 -> 0.041666667 | P32: =IF(OR(I32="",J32="",N32="",O32=""),"",((J32+O32)-(I32+N32))) | Q32: =IF(OR(H32="",J32="",L32="",O32=""),"",IF((J32+O32)<(H32+L32),"Ahead",IF((J32+O32)=(H32+L32),"On-Time","Delayed"))) | R32: =IF(F32=100%,"Completed",IF(F32=0,"Not Started","In Progress")) -> Not Started
A33: =A32+1 -> 15 | B33: Track installation (line 1) | C33: =1/24 -> 0.041666667 | D33: =(C33/$C$47)*100 -> 2.0408163 | E33: =D33*F33 -> 0 | G33: 46312 | H33: 46312 | K33: =L32 -> 1.1666667 | L33: =K33+C33 -> 1.2083333 | M33: =L33-K33 -> 0.041666667 | P33: =IF(OR(I33="",J33="",N33="",O33=""),"",((J33+O33)-(I33+N33))) | Q33: =IF(OR(H33="",J33="",L33="",O33=""),"",IF((J33+O33)<(H33+L33),"Ahead",IF((J33+O33)=(H33+L33),"On-Time","Delayed"))) | R33: =IF(F33=100%,"Completed",IF(F33=0,"Not Started","In Progress")) -> Not Started
A34: =A33+1 -> 16 | B34: Track installation (line 3) | C34: =1/24 -> 0.041666667 | D34: =(C34/$C$47)*100 -> 2.0408163 | E34: =D34*F34 -> 0 | G34: 46312 | H34: 46312 | K34: =L33 -> 1.2083333 | L34: =K34+C34 -> 1.25 | M34: =L34-K34 -> 0.041666667 | P34: =IF(OR(I34="",J34="",N34="",O34=""),"",((J34+O34)-(I34+N34))) | Q34: =IF(OR(H34="",J34="",L34="",O34=""),"",IF((J34+O34)<(H34+L34),"Ahead",IF((J34+O34)=(H34+L34),"On-Time","Delayed"))) | R34: =IF(F34=100%,"Completed",IF(F34=0,"Not Started","In Progress")) -> Not Started
A35: =A34+1 -> 17 | B35: First and Second Ballasting/Tamping/Stabilization/Profiling (line 1) | C35: =1/24 -> 0.041666667 | D35: =(C35/$C$47)*100 -> 2.0408163 | E35: =D35*F35 -> 0 | G35: 46312 | H35: 46312 | K35: =L34 -> 1.25 | L35: =K35+C35 -> 1.2916667 | M35: =L35-K35 -> 0.041666667 | P35: =IF(OR(I35="",J35="",N35="",O35=""),"",((J35+O35)-(I35+N35))) | Q35: =IF(OR(H35="",J35="",L35="",O35=""),"",IF((J35+O35)<(H35+L35),"Ahead",IF((J35+O35)=(H35+L35),"On-Time","Delayed"))) | R35: =IF(F35=100%,"Completed",IF(F35=0,"Not Started","In Progress")) -> Not Started
A36: =A35+1 -> 18 | B36: Final Ballasting/Tamping/Stabilization/Profiling (line 1) | C36: =1/24 -> 0.041666667 | D36: =(C36/$C$47)*100 -> 2.0408163 | E36: =D36*F36 -> 0 | G36: 46312 | H36: 46312 | K36: =L35 -> 1.2916667 | L36: =K36+C36 -> 1.3333333 | M36: =L36-K36 -> 0.041666667 | P36: =IF(OR(I36="",J36="",N36="",O36=""),"",((J36+O36)-(I36+N36))) | Q36: =IF(OR(H36="",J36="",L36="",O36=""),"",IF((J36+O36)<(H36+L36),"Ahead",IF((J36+O36)=(H36+L36),"On-Time","Delayed"))) | R36: =IF(F36=100%,"Completed",IF(F36=0,"Not Started","In Progress")) -> Not Started
A37: =A36+1 -> 19 | B37: TSO OTMP moves from line 1 to Line 3 TK 121+000 | C37: =1/24 -> 0.041666667 | D37: =(C37/$C$47)*100 -> 2.0408163 | E37: =D37*F37 -> 0 | G37: 46312 | H37: 46312 | K37: 1.3333333 | L37: =K37+C37 -> 1.375 | M37: =L37-K37 -> 0.041666667 | P37: =IF(OR(I37="",J37="",N37="",O37=""),"",((J37+O37)-(I37+N37))) | Q37: =IF(OR(H37="",J37="",L37="",O37=""),"",IF((J37+O37)<(H37+L37),"Ahead",IF((J37+O37)=(H37+L37),"On-Time","Delayed"))) | R37: =IF(F37=100%,"Completed",IF(F37=0,"Not Started","In Progress")) -> Not Started | S37: OTMP Movement
A38: 20 | B38: ATW - 2U (out of destressing) (line 1) | C38: 0.083333333 | D38: =(C38/$C$47)*100 -> 4.0816327 | E38: =D38*F38 -> 0 | G38: 46312 | H38: 46312 | K38: =L37 -> 1.375 | L38: =K38+C38 -> 1.4583333 | M38: =L38-K38 -> 0.083333333 | P38: =IF(OR(I38="",J38="",N38="",O38=""),"",((J38+O38)-(I38+N38))) | Q38: =IF(OR(H38="",J38="",L38="",O38=""),"",IF((J38+O38)<(H38+L38),"Ahead",IF((J38+O38)=(H38+L38),"On-Time","Delayed"))) | R38: =IF(F38=100%,"Completed",IF(F38=0,"Not Started","In Progress")) -> Not Started
A39: =A38+1 -> 21 | B39: ATW - 2U (out of destressing) (line 3) | C39: 0.083333333 | D39: =(C39/$C$47)*100 -> 4.0816327 | E39: =D39*F39 -> 0 | G39: 46312 | H39: 46312 | K39: =L38 -> 1.4583333 | L39: =K39+C39 -> 1.5416667 | M39: =L39-K39 -> 0.083333333 | P39: =IF(OR(I39="",J39="",N39="",O39=""),"",((J39+O39)-(I39+N39))) | Q39: =IF(OR(H39="",J39="",L39="",O39=""),"",IF((J39+O39)<(H39+L39),"Ahead",IF((J39+O39)=(H39+L39),"On-Time","Delayed"))) | R39: =IF(F39=100%,"Completed",IF(F39=0,"Not Started","In Progress")) -> Not Started
A40: =A39+1 -> 22 | B40: First and Second Ballasting/Tamping/Stabilization/Profiling (line 3) | C40: =1/24 -> 0.041666667 | D40: =(C40/$C$47)*100 -> 2.0408163 | E40: =D40*F40 -> 0 | G40: 46312 | H40: 46312 | K40: =L39 -> 1.5416667 | L40: =K40+C40 -> 1.5833333 | M40: =L40-K40 -> 0.041666667 | P40: =IF(OR(I40="",J40="",N40="",O40=""),"",((J40+O40)-(I40+N40))) | Q40: =IF(OR(H40="",J40="",L40="",O40=""),"",IF((J40+O40)<(H40+L40),"Ahead",IF((J40+O40)=(H40+L40),"On-Time","Delayed"))) | R40: =IF(F40=100%,"Completed",IF(F40=0,"Not Started","In Progress")) -> Not Started | S40: After OTMP pass to location
A41: =A40+1 -> 23 | B41: Final Ballasting/Tamping/Stabilization/Profiling (line 3) | C41: =1/24 -> 0.041666667 | D41: =(C41/$C$47)*100 -> 2.0408163 | E41: =D41*F41 -> 0 | G41: 46312 | H41: 46312 | K41: =L40 -> 1.5833333 | L41: =K41+C41 -> 1.625 | M41: =L41-K41 -> 0.041666667 | P41: =IF(OR(I41="",J41="",N41="",O41=""),"",((J41+O41)-(I41+N41))) | Q41: =IF(OR(H41="",J41="",L41="",O41=""),"",IF((J41+O41)<(H41+L41),"Ahead",IF((J41+O41)=(H41+L41),"On-Time","Delayed"))) | R41: =IF(F41=100%,"Completed",IF(F41=0,"Not Started","In Progress")) -> Not Started
A42: =A41+1 -> 24 | B42: TSO Back towards station 29 | C42: =2/24 -> 0.083333333 | G42: 46312 | H42: 46312 | K42: =L41 -> 1.625 | L42: 1.5833333 | M42: 0.083333333 | P42: =IF(OR(I42="",J42="",N42="",O42=""),"",((J42+O42)-(I42+N42))) | Q42: =IF(OR(H42="",J42="",L42="",O42=""),"",IF((J42+O42)<(H42+L42),"Ahead",IF((J42+O42)=(H42+L42),"On-Time","Delayed"))) | R42: =IF(F42=100%,"Completed",IF(F42=0,"Not Started","In Progress")) -> Not Started | S42: OTMP Movement
A43: =A42+1 -> 25 | B43: No Work Hours due to tempratare | G43: 46312 | H43: 46312 | P43: =IF(OR(I43="",J43="",N43="",O43=""),"",((J43+O43)-(I43+N43))) | Q43: =IF(OR(H43="",J43="",L43="",O43=""),"",IF((J43+O43)<(H43+L43),"Ahead",IF((J43+O43)=(H43+L43),"On-Time","Delayed"))) | R43: =IF(F43=100%,"Completed",IF(F43=0,"Not Started","In Progress")) -> Not Started | S43: Rest Hours
A44: =A43+1 -> 26 | B44: Destressing (including 2 ATW) (line 1) | C44: =4/24 -> 0.16666667 | D44: =(C44/$C$47)*100 -> 8.1632653 | E44: =D44*F44 -> 0 | G44: 46312 | H44: 46312 | K44: =L41 -> 1.625 | L44: =K44+C44 -> 1.7916667 | M44: =L44-K44 -> 0.16666667 | P44: =IF(OR(I44="",J44="",N44="",O44=""),"",((J44+O44)-(I44+N44))) | Q44: =IF(OR(H44="",J44="",L44="",O44=""),"",IF((J44+O44)<(H44+L44),"Ahead",IF((J44+O44)=(H44+L44),"On-Time","Delayed"))) | R44: =IF(F44=100%,"Completed",IF(F44=0,"Not Started","In Progress")) -> Not Started
A45: =A44+1 -> 27 | B45: Destressing (including 2 ATW) (line 3) | C45: =4/24 -> 0.16666667 | D45: =(C45/$C$47)*100 -> 8.1632653 | E45: =D45*F45 -> 0 | G45: 46312 | H45: 46312 | K45: =L44 -> 1.7916667 | L45: =K45+C45 -> 1.9583333 | M45: =L45-K45 -> 0.16666667 | P45: =IF(OR(I45="",J45="",N45="",O45=""),"",((J45+O45)-(I45+N45))) | Q45: =IF(OR(H45="",J45="",L45="",O45=""),"",IF((J45+O45)<(H45+L45),"Ahead",IF((J45+O45)=(H45+L45),"On-Time","Delayed"))) | R45: =IF(F45=100%,"Completed",IF(F45=0,"Not Started","In Progress")) -> Not Started
A46: =A45+1 -> 28 | B46: Finishing (including final grinding, welding stamp, UT, inspection, etc.) | C46: =1/24 -> 0.041666667 | D46: =(C46/$C$47)*100 -> 2.0408163 | E46: =D46*F46 -> 0 | G46: 46312 | H46: 46312 | K46: =L45 -> 1.9583333 | L46: =K46+C46 -> 2 | M46: =L46-K46 -> 0.041666667 | P46: =IF(OR(I46="",J46="",N46="",O46=""),"",((J46+O46)-(I46+N46))) | Q46: =IF(OR(H46="",J46="",L46="",O46=""),"",IF((J46+O46)<(H46+L46),"Ahead",IF((J46+O46)=(H46+L46),"On-Time","Delayed"))) | R46: =IF(F46=100%,"Completed",IF(F46=0,"Not Started","In Progress")) -> Not Started
C47: =SUM(C20:C46)-C42 -> 2.0416667 | D47: =SUM(D20:D46) -> 99.989184 | E47: =SUM(E20:E46)/D47 -> 0 | F47: Progress
...

Sheet Charts
A3: Culvert | B3: Total Hrs (Plan) | C3: Completed | D3: Remaining
A4: C028 (116+700) | B4: ='Shutdown02 Progress'!C46 -> 0.041666667 | C4: ='Shutdown02 Progress'!E47 -> 0 | D4: =1-C4 -> 1
A5: C052 (124+415) | B5: ='Shutdown02 Progress'!C79 -> 0.29166667 | C5: ='Shutdown02 Progress'!E80 -> 0 | D5: =1-C5 -> 1
A6: C053 (124+585) | B6: ='Shutdown02 Progress'!C112 -> 0.041666667 | C6: ='Shutdown02 Progress'!E113 -> 0 | D6: =1-C6 -> 1
A7: C067 (129+103) | B7: ='Shutdown02 Progress'!C145 -> 0.16666667 | C7: ='Shutdown02 Progress'!E146 -> 0 | D7: =1-C7 -> 1
A8: C070 (132+198) | B8: ='Shutdown02 Progress'!C177 -> 0.16666667 | C8: ='Shutdown02 Progress'!E179 -> 0 | D8: =1-C8 -> 1
A9: OVERALL | B9: =SUM(B4,B5,B6,B7,B8) -> 0.70833333 | C9: =(B4*C4+B5*C5+B6*C6+B7*C7+B8*C8)/B9 -> 0 | D9: =1-C9 -> 1
A11: DURATION COMPLETION BY CULVERT
